2025-08-28 09:32:42 | ERROR    | phase1_sync | MySQL 連接失敗：'cryptography' package is required for sha256_password or caching_sha2_password auth methods
2025-08-28 09:32:42 | ERROR    | phase1_sync | 程式發生嚴重錯誤：'cryptography' package is required for sha256_password or caching_sha2_password auth methods
Traceback (most recent call last):
  File "/app/scripts/phase1/main.py", line 407, in main
    syncer = CrossTableSync()
             ^^^^^^^^^^^^^^^^
  File "/app/scripts/phase1/main.py", line 52, in __init__
    self.mysql = MySQLConnector(self.db_config['mysql'], logger)
                 ^^^^^^^^^^^^^^^^^^^^^^^^^^^^^^^^^^^^^^^^^^^^^^^
  File "/app/scripts/phase1/mysql_connector.py", line 30, in __init__
    self._init_connection()
  File "/app/scripts/phase1/mysql_connector.py", line 55, in _init_connection
    with self.engine.connect() as conn:
         ^^^^^^^^^^^^^^^^^^^^^
  File "/usr/local/lib/python3.11/site-packages/sqlalchemy/engine/base.py", line 3277, in connect
    return self._connection_cls(self)
           ^^^^^^^^^^^^^^^^^^^^^^^^^^
  File "/usr/local/lib/python3.11/site-packages/sqlalchemy/engine/base.py", line 143, in __init__
    self._dbapi_connection = engine.raw_connection()
                             ^^^^^^^^^^^^^^^^^^^^^^^
  File "/usr/local/lib/python3.11/site-packages/sqlalchemy/engine/base.py", line 3301, in raw_connection
    return self.pool.connect()
           ^^^^^^^^^^^^^^^^^^^
  File "/usr/local/lib/python3.11/site-packages/sqlalchemy/pool/base.py", line 447, in connect
    return _ConnectionFairy._checkout(self)
           ^^^^^^^^^^^^^^^^^^^^^^^^^^^^^^^^
  File "/usr/local/lib/python3.11/site-packages/sqlalchemy/pool/base.py", line 1264, in _checkout
    fairy = _ConnectionRecord.checkout(pool)
            ^^^^^^^^^^^^^^^^^^^^^^^^^^^^^^^^
  File "/usr/local/lib/python3.11/site-packages/sqlalchemy/pool/base.py", line 711, in checkout
    rec = pool._do_get()
          ^^^^^^^^^^^^^^
  File "/usr/local/lib/python3.11/site-packages/sqlalchemy/pool/impl.py", line 177, in _do_get
    with util.safe_reraise():
  File "/usr/local/lib/python3.11/site-packages/sqlalchemy/util/langhelpers.py", line 224, in __exit__
    raise exc_value.with_traceback(exc_tb)
  File "/usr/local/lib/python3.11/site-packages/sqlalchemy/pool/impl.py", line 175, in _do_get
    return self._create_connection()
           ^^^^^^^^^^^^^^^^^^^^^^^^^
  File "/usr/local/lib/python3.11/site-packages/sqlalchemy/pool/base.py", line 388, in _create_connection
    return _ConnectionRecord(self)
           ^^^^^^^^^^^^^^^^^^^^^^^
  File "/usr/local/lib/python3.11/site-packages/sqlalchemy/pool/base.py", line 673, in __init__
    self.__connect()
  File "/usr/local/lib/python3.11/site-packages/sqlalchemy/pool/base.py", line 899, in __connect
    with util.safe_reraise():
  File "/usr/local/lib/python3.11/site-packages/sqlalchemy/util/langhelpers.py", line 224, in __exit__
    raise exc_value.with_traceback(exc_tb)
  File "/usr/local/lib/python3.11/site-packages/sqlalchemy/pool/base.py", line 895, in __connect
    self.dbapi_connection = connection = pool._invoke_creator(self)
                                         ^^^^^^^^^^^^^^^^^^^^^^^^^^
  File "/usr/local/lib/python3.11/site-packages/sqlalchemy/engine/create.py", line 661, in connect
    return dialect.connect(*cargs, **cparams)
           ^^^^^^^^^^^^^^^^^^^^^^^^^^^^^^^^^^
  File "/usr/local/lib/python3.11/site-packages/sqlalchemy/engine/default.py", line 629, in connect
    return self.loaded_dbapi.connect(*cargs, **cparams)  # type: ignore[no-any-return]  # NOQA: E501
           ^^^^^^^^^^^^^^^^^^^^^^^^^^^^^^^^^^^^^^^^^^^^
  File "/usr/local/lib/python3.11/site-packages/pymysql/connections.py", line 365, in __init__
    self.connect()
  File "/usr/local/lib/python3.11/site-packages/pymysql/connections.py", line 681, in connect
    self._request_authentication()
  File "/usr/local/lib/python3.11/site-packages/pymysql/connections.py", line 980, in _request_authentication
    auth_packet = _auth.caching_sha2_password_auth(self, auth_packet)
                  ^^^^^^^^^^^^^^^^^^^^^^^^^^^^^^^^^^^^^^^^^^^^^^^^^^^
  File "/usr/local/lib/python3.11/site-packages/pymysql/_auth.py", line 271, in caching_sha2_password_auth
    data = sha2_rsa_encrypt(conn.password, conn.salt, conn.server_public_key)
           ^^^^^^^^^^^^^^^^^^^^^^^^^^^^^^^^^^^^^^^^^^^^^^^^^^^^^^^^^^^^^^^^^^
  File "/usr/local/lib/python3.11/site-packages/pymysql/_auth.py", line 144, in sha2_rsa_encrypt
    raise RuntimeError(
RuntimeError: 'cryptography' package is required for sha256_password or caching_sha2_password auth methods
2025-08-28 09:32:43 | ERROR    | phase1_sync | MySQL 連接失敗：'cryptography' package is required for sha256_password or caching_sha2_password auth methods
2025-08-28 09:32:43 | ERROR    | phase1_sync | 程式發生嚴重錯誤：'cryptography' package is required for sha256_password or caching_sha2_password auth methods
Traceback (most recent call last):
  File "/app/scripts/phase1/main.py", line 407, in main
    syncer = CrossTableSync()
             ^^^^^^^^^^^^^^^^
  File "/app/scripts/phase1/main.py", line 52, in __init__
    self.mysql = MySQLConnector(self.db_config['mysql'], logger)
                 ^^^^^^^^^^^^^^^^^^^^^^^^^^^^^^^^^^^^^^^^^^^^^^^
  File "/app/scripts/phase1/mysql_connector.py", line 30, in __init__
    self._init_connection()
  File "/app/scripts/phase1/mysql_connector.py", line 55, in _init_connection
    with self.engine.connect() as conn:
         ^^^^^^^^^^^^^^^^^^^^^
  File "/usr/local/lib/python3.11/site-packages/sqlalchemy/engine/base.py", line 3277, in connect
    return self._connection_cls(self)
           ^^^^^^^^^^^^^^^^^^^^^^^^^^
  File "/usr/local/lib/python3.11/site-packages/sqlalchemy/engine/base.py", line 143, in __init__
    self._dbapi_connection = engine.raw_connection()
                             ^^^^^^^^^^^^^^^^^^^^^^^
  File "/usr/local/lib/python3.11/site-packages/sqlalchemy/engine/base.py", line 3301, in raw_connection
    return self.pool.connect()
           ^^^^^^^^^^^^^^^^^^^
  File "/usr/local/lib/python3.11/site-packages/sqlalchemy/pool/base.py", line 447, in connect
    return _ConnectionFairy._checkout(self)
           ^^^^^^^^^^^^^^^^^^^^^^^^^^^^^^^^
  File "/usr/local/lib/python3.11/site-packages/sqlalchemy/pool/base.py", line 1264, in _checkout
    fairy = _ConnectionRecord.checkout(pool)
            ^^^^^^^^^^^^^^^^^^^^^^^^^^^^^^^^
  File "/usr/local/lib/python3.11/site-packages/sqlalchemy/pool/base.py", line 711, in checkout
    rec = pool._do_get()
          ^^^^^^^^^^^^^^
  File "/usr/local/lib/python3.11/site-packages/sqlalchemy/pool/impl.py", line 177, in _do_get
    with util.safe_reraise():
  File "/usr/local/lib/python3.11/site-packages/sqlalchemy/util/langhelpers.py", line 224, in __exit__
    raise exc_value.with_traceback(exc_tb)
  File "/usr/local/lib/python3.11/site-packages/sqlalchemy/pool/impl.py", line 175, in _do_get
    return self._create_connection()
           ^^^^^^^^^^^^^^^^^^^^^^^^^
  File "/usr/local/lib/python3.11/site-packages/sqlalchemy/pool/base.py", line 388, in _create_connection
    return _ConnectionRecord(self)
           ^^^^^^^^^^^^^^^^^^^^^^^
  File "/usr/local/lib/python3.11/site-packages/sqlalchemy/pool/base.py", line 673, in __init__
    self.__connect()
  File "/usr/local/lib/python3.11/site-packages/sqlalchemy/pool/base.py", line 899, in __connect
    with util.safe_reraise():
  File "/usr/local/lib/python3.11/site-packages/sqlalchemy/util/langhelpers.py", line 224, in __exit__
    raise exc_value.with_traceback(exc_tb)
  File "/usr/local/lib/python3.11/site-packages/sqlalchemy/pool/base.py", line 895, in __connect
    self.dbapi_connection = connection = pool._invoke_creator(self)
                                         ^^^^^^^^^^^^^^^^^^^^^^^^^^
  File "/usr/local/lib/python3.11/site-packages/sqlalchemy/engine/create.py", line 661, in connect
    return dialect.connect(*cargs, **cparams)
           ^^^^^^^^^^^^^^^^^^^^^^^^^^^^^^^^^^
  File "/usr/local/lib/python3.11/site-packages/sqlalchemy/engine/default.py", line 629, in connect
    return self.loaded_dbapi.connect(*cargs, **cparams)  # type: ignore[no-any-return]  # NOQA: E501
           ^^^^^^^^^^^^^^^^^^^^^^^^^^^^^^^^^^^^^^^^^^^^
  File "/usr/local/lib/python3.11/site-packages/pymysql/connections.py", line 365, in __init__
    self.connect()
  File "/usr/local/lib/python3.11/site-packages/pymysql/connections.py", line 681, in connect
    self._request_authentication()
  File "/usr/local/lib/python3.11/site-packages/pymysql/connections.py", line 980, in _request_authentication
    auth_packet = _auth.caching_sha2_password_auth(self, auth_packet)
                  ^^^^^^^^^^^^^^^^^^^^^^^^^^^^^^^^^^^^^^^^^^^^^^^^^^^
  File "/usr/local/lib/python3.11/site-packages/pymysql/_auth.py", line 271, in caching_sha2_password_auth
    data = sha2_rsa_encrypt(conn.password, conn.salt, conn.server_public_key)
           ^^^^^^^^^^^^^^^^^^^^^^^^^^^^^^^^^^^^^^^^^^^^^^^^^^^^^^^^^^^^^^^^^^
  File "/usr/local/lib/python3.11/site-packages/pymysql/_auth.py", line 144, in sha2_rsa_encrypt
    raise RuntimeError(
RuntimeError: 'cryptography' package is required for sha256_password or caching_sha2_password auth methods
2025-08-28 09:32:45 | ERROR    | phase1_sync | MySQL 連接失敗：'cryptography' package is required for sha256_password or caching_sha2_password auth methods
2025-08-28 09:32:45 | ERROR    | phase1_sync | 程式發生嚴重錯誤：'cryptography' package is required for sha256_password or caching_sha2_password auth methods
Traceback (most recent call last):
  File "/app/scripts/phase1/main.py", line 407, in main
    syncer = CrossTableSync()
             ^^^^^^^^^^^^^^^^
  File "/app/scripts/phase1/main.py", line 52, in __init__
    self.mysql = MySQLConnector(self.db_config['mysql'], logger)
                 ^^^^^^^^^^^^^^^^^^^^^^^^^^^^^^^^^^^^^^^^^^^^^^^
  File "/app/scripts/phase1/mysql_connector.py", line 30, in __init__
    self._init_connection()
  File "/app/scripts/phase1/mysql_connector.py", line 55, in _init_connection
    with self.engine.connect() as conn:
         ^^^^^^^^^^^^^^^^^^^^^
  File "/usr/local/lib/python3.11/site-packages/sqlalchemy/engine/base.py", line 3277, in connect
    return self._connection_cls(self)
           ^^^^^^^^^^^^^^^^^^^^^^^^^^
  File "/usr/local/lib/python3.11/site-packages/sqlalchemy/engine/base.py", line 143, in __init__
    self._dbapi_connection = engine.raw_connection()
                             ^^^^^^^^^^^^^^^^^^^^^^^
  File "/usr/local/lib/python3.11/site-packages/sqlalchemy/engine/base.py", line 3301, in raw_connection
    return self.pool.connect()
           ^^^^^^^^^^^^^^^^^^^
  File "/usr/local/lib/python3.11/site-packages/sqlalchemy/pool/base.py", line 447, in connect
    return _ConnectionFairy._checkout(self)
           ^^^^^^^^^^^^^^^^^^^^^^^^^^^^^^^^
  File "/usr/local/lib/python3.11/site-packages/sqlalchemy/pool/base.py", line 1264, in _checkout
    fairy = _ConnectionRecord.checkout(pool)
            ^^^^^^^^^^^^^^^^^^^^^^^^^^^^^^^^
  File "/usr/local/lib/python3.11/site-packages/sqlalchemy/pool/base.py", line 711, in checkout
    rec = pool._do_get()
          ^^^^^^^^^^^^^^
  File "/usr/local/lib/python3.11/site-packages/sqlalchemy/pool/impl.py", line 177, in _do_get
    with util.safe_reraise():
  File "/usr/local/lib/python3.11/site-packages/sqlalchemy/util/langhelpers.py", line 224, in __exit__
    raise exc_value.with_traceback(exc_tb)
  File "/usr/local/lib/python3.11/site-packages/sqlalchemy/pool/impl.py", line 175, in _do_get
    return self._create_connection()
           ^^^^^^^^^^^^^^^^^^^^^^^^^
  File "/usr/local/lib/python3.11/site-packages/sqlalchemy/pool/base.py", line 388, in _create_connection
    return _ConnectionRecord(self)
           ^^^^^^^^^^^^^^^^^^^^^^^
  File "/usr/local/lib/python3.11/site-packages/sqlalchemy/pool/base.py", line 673, in __init__
    self.__connect()
  File "/usr/local/lib/python3.11/site-packages/sqlalchemy/pool/base.py", line 899, in __connect
    with util.safe_reraise():
  File "/usr/local/lib/python3.11/site-packages/sqlalchemy/util/langhelpers.py", line 224, in __exit__
    raise exc_value.with_traceback(exc_tb)
  File "/usr/local/lib/python3.11/site-packages/sqlalchemy/pool/base.py", line 895, in __connect
    self.dbapi_connection = connection = pool._invoke_creator(self)
                                         ^^^^^^^^^^^^^^^^^^^^^^^^^^
  File "/usr/local/lib/python3.11/site-packages/sqlalchemy/engine/create.py", line 661, in connect
    return dialect.connect(*cargs, **cparams)
           ^^^^^^^^^^^^^^^^^^^^^^^^^^^^^^^^^^
  File "/usr/local/lib/python3.11/site-packages/sqlalchemy/engine/default.py", line 629, in connect
    return self.loaded_dbapi.connect(*cargs, **cparams)  # type: ignore[no-any-return]  # NOQA: E501
           ^^^^^^^^^^^^^^^^^^^^^^^^^^^^^^^^^^^^^^^^^^^^
  File "/usr/local/lib/python3.11/site-packages/pymysql/connections.py", line 365, in __init__
    self.connect()
  File "/usr/local/lib/python3.11/site-packages/pymysql/connections.py", line 681, in connect
    self._request_authentication()
  File "/usr/local/lib/python3.11/site-packages/pymysql/connections.py", line 980, in _request_authentication
    auth_packet = _auth.caching_sha2_password_auth(self, auth_packet)
                  ^^^^^^^^^^^^^^^^^^^^^^^^^^^^^^^^^^^^^^^^^^^^^^^^^^^
  File "/usr/local/lib/python3.11/site-packages/pymysql/_auth.py", line 271, in caching_sha2_password_auth
    data = sha2_rsa_encrypt(conn.password, conn.salt, conn.server_public_key)
           ^^^^^^^^^^^^^^^^^^^^^^^^^^^^^^^^^^^^^^^^^^^^^^^^^^^^^^^^^^^^^^^^^^
  File "/usr/local/lib/python3.11/site-packages/pymysql/_auth.py", line 144, in sha2_rsa_encrypt
    raise RuntimeError(
RuntimeError: 'cryptography' package is required for sha256_password or caching_sha2_password auth methods
2025-08-28 09:32:46 | ERROR    | phase1_sync | MySQL 連接失敗：'cryptography' package is required for sha256_password or caching_sha2_password auth methods
2025-08-28 09:32:46 | ERROR    | phase1_sync | 程式發生嚴重錯誤：'cryptography' package is required for sha256_password or caching_sha2_password auth methods
Traceback (most recent call last):
  File "/app/scripts/phase1/main.py", line 407, in main
    syncer = CrossTableSync()
             ^^^^^^^^^^^^^^^^
  File "/app/scripts/phase1/main.py", line 52, in __init__
    self.mysql = MySQLConnector(self.db_config['mysql'], logger)
                 ^^^^^^^^^^^^^^^^^^^^^^^^^^^^^^^^^^^^^^^^^^^^^^^
  File "/app/scripts/phase1/mysql_connector.py", line 30, in __init__
    self._init_connection()
  File "/app/scripts/phase1/mysql_connector.py", line 55, in _init_connection
    with self.engine.connect() as conn:
         ^^^^^^^^^^^^^^^^^^^^^
  File "/usr/local/lib/python3.11/site-packages/sqlalchemy/engine/base.py", line 3277, in connect
    return self._connection_cls(self)
           ^^^^^^^^^^^^^^^^^^^^^^^^^^
  File "/usr/local/lib/python3.11/site-packages/sqlalchemy/engine/base.py", line 143, in __init__
    self._dbapi_connection = engine.raw_connection()
                             ^^^^^^^^^^^^^^^^^^^^^^^
  File "/usr/local/lib/python3.11/site-packages/sqlalchemy/engine/base.py", line 3301, in raw_connection
    return self.pool.connect()
           ^^^^^^^^^^^^^^^^^^^
  File "/usr/local/lib/python3.11/site-packages/sqlalchemy/pool/base.py", line 447, in connect
    return _ConnectionFairy._checkout(self)
           ^^^^^^^^^^^^^^^^^^^^^^^^^^^^^^^^
  File "/usr/local/lib/python3.11/site-packages/sqlalchemy/pool/base.py", line 1264, in _checkout
    fairy = _ConnectionRecord.checkout(pool)
            ^^^^^^^^^^^^^^^^^^^^^^^^^^^^^^^^
  File "/usr/local/lib/python3.11/site-packages/sqlalchemy/pool/base.py", line 711, in checkout
    rec = pool._do_get()
          ^^^^^^^^^^^^^^
  File "/usr/local/lib/python3.11/site-packages/sqlalchemy/pool/impl.py", line 177, in _do_get
    with util.safe_reraise():
  File "/usr/local/lib/python3.11/site-packages/sqlalchemy/util/langhelpers.py", line 224, in __exit__
    raise exc_value.with_traceback(exc_tb)
  File "/usr/local/lib/python3.11/site-packages/sqlalchemy/pool/impl.py", line 175, in _do_get
    return self._create_connection()
           ^^^^^^^^^^^^^^^^^^^^^^^^^
  File "/usr/local/lib/python3.11/site-packages/sqlalchemy/pool/base.py", line 388, in _create_connection
    return _ConnectionRecord(self)
           ^^^^^^^^^^^^^^^^^^^^^^^
  File "/usr/local/lib/python3.11/site-packages/sqlalchemy/pool/base.py", line 673, in __init__
    self.__connect()
  File "/usr/local/lib/python3.11/site-packages/sqlalchemy/pool/base.py", line 899, in __connect
    with util.safe_reraise():
  File "/usr/local/lib/python3.11/site-packages/sqlalchemy/util/langhelpers.py", line 224, in __exit__
    raise exc_value.with_traceback(exc_tb)
  File "/usr/local/lib/python3.11/site-packages/sqlalchemy/pool/base.py", line 895, in __connect
    self.dbapi_connection = connection = pool._invoke_creator(self)
                                         ^^^^^^^^^^^^^^^^^^^^^^^^^^
  File "/usr/local/lib/python3.11/site-packages/sqlalchemy/engine/create.py", line 661, in connect
    return dialect.connect(*cargs, **cparams)
           ^^^^^^^^^^^^^^^^^^^^^^^^^^^^^^^^^^
  File "/usr/local/lib/python3.11/site-packages/sqlalchemy/engine/default.py", line 629, in connect
    return self.loaded_dbapi.connect(*cargs, **cparams)  # type: ignore[no-any-return]  # NOQA: E501
           ^^^^^^^^^^^^^^^^^^^^^^^^^^^^^^^^^^^^^^^^^^^^
  File "/usr/local/lib/python3.11/site-packages/pymysql/connections.py", line 365, in __init__
    self.connect()
  File "/usr/local/lib/python3.11/site-packages/pymysql/connections.py", line 681, in connect
    self._request_authentication()
  File "/usr/local/lib/python3.11/site-packages/pymysql/connections.py", line 980, in _request_authentication
    auth_packet = _auth.caching_sha2_password_auth(self, auth_packet)
                  ^^^^^^^^^^^^^^^^^^^^^^^^^^^^^^^^^^^^^^^^^^^^^^^^^^^
  File "/usr/local/lib/python3.11/site-packages/pymysql/_auth.py", line 271, in caching_sha2_password_auth
    data = sha2_rsa_encrypt(conn.password, conn.salt, conn.server_public_key)
           ^^^^^^^^^^^^^^^^^^^^^^^^^^^^^^^^^^^^^^^^^^^^^^^^^^^^^^^^^^^^^^^^^^
  File "/usr/local/lib/python3.11/site-packages/pymysql/_auth.py", line 144, in sha2_rsa_encrypt
    raise RuntimeError(
RuntimeError: 'cryptography' package is required for sha256_password or caching_sha2_password auth methods
2025-08-28 09:32:48 | ERROR    | phase1_sync | MySQL 連接失敗：'cryptography' package is required for sha256_password or caching_sha2_password auth methods
2025-08-28 09:32:48 | ERROR    | phase1_sync | 程式發生嚴重錯誤：'cryptography' package is required for sha256_password or caching_sha2_password auth methods
Traceback (most recent call last):
  File "/app/scripts/phase1/main.py", line 407, in main
    syncer = CrossTableSync()
             ^^^^^^^^^^^^^^^^
  File "/app/scripts/phase1/main.py", line 52, in __init__
    self.mysql = MySQLConnector(self.db_config['mysql'], logger)
                 ^^^^^^^^^^^^^^^^^^^^^^^^^^^^^^^^^^^^^^^^^^^^^^^
  File "/app/scripts/phase1/mysql_connector.py", line 30, in __init__
    self._init_connection()
  File "/app/scripts/phase1/mysql_connector.py", line 55, in _init_connection
    with self.engine.connect() as conn:
         ^^^^^^^^^^^^^^^^^^^^^
  File "/usr/local/lib/python3.11/site-packages/sqlalchemy/engine/base.py", line 3277, in connect
    return self._connection_cls(self)
           ^^^^^^^^^^^^^^^^^^^^^^^^^^
  File "/usr/local/lib/python3.11/site-packages/sqlalchemy/engine/base.py", line 143, in __init__
    self._dbapi_connection = engine.raw_connection()
                             ^^^^^^^^^^^^^^^^^^^^^^^
  File "/usr/local/lib/python3.11/site-packages/sqlalchemy/engine/base.py", line 3301, in raw_connection
    return self.pool.connect()
           ^^^^^^^^^^^^^^^^^^^
  File "/usr/local/lib/python3.11/site-packages/sqlalchemy/pool/base.py", line 447, in connect
    return _ConnectionFairy._checkout(self)
           ^^^^^^^^^^^^^^^^^^^^^^^^^^^^^^^^
  File "/usr/local/lib/python3.11/site-packages/sqlalchemy/pool/base.py", line 1264, in _checkout
    fairy = _ConnectionRecord.checkout(pool)
            ^^^^^^^^^^^^^^^^^^^^^^^^^^^^^^^^
  File "/usr/local/lib/python3.11/site-packages/sqlalchemy/pool/base.py", line 711, in checkout
    rec = pool._do_get()
          ^^^^^^^^^^^^^^
  File "/usr/local/lib/python3.11/site-packages/sqlalchemy/pool/impl.py", line 177, in _do_get
    with util.safe_reraise():
  File "/usr/local/lib/python3.11/site-packages/sqlalchemy/util/langhelpers.py", line 224, in __exit__
    raise exc_value.with_traceback(exc_tb)
  File "/usr/local/lib/python3.11/site-packages/sqlalchemy/pool/impl.py", line 175, in _do_get
    return self._create_connection()
           ^^^^^^^^^^^^^^^^^^^^^^^^^
  File "/usr/local/lib/python3.11/site-packages/sqlalchemy/pool/base.py", line 388, in _create_connection
    return _ConnectionRecord(self)
           ^^^^^^^^^^^^^^^^^^^^^^^
  File "/usr/local/lib/python3.11/site-packages/sqlalchemy/pool/base.py", line 673, in __init__
    self.__connect()
  File "/usr/local/lib/python3.11/site-packages/sqlalchemy/pool/base.py", line 899, in __connect
    with util.safe_reraise():
  File "/usr/local/lib/python3.11/site-packages/sqlalchemy/util/langhelpers.py", line 224, in __exit__
    raise exc_value.with_traceback(exc_tb)
  File "/usr/local/lib/python3.11/site-packages/sqlalchemy/pool/base.py", line 895, in __connect
    self.dbapi_connection = connection = pool._invoke_creator(self)
                                         ^^^^^^^^^^^^^^^^^^^^^^^^^^
  File "/usr/local/lib/python3.11/site-packages/sqlalchemy/engine/create.py", line 661, in connect
    return dialect.connect(*cargs, **cparams)
           ^^^^^^^^^^^^^^^^^^^^^^^^^^^^^^^^^^
  File "/usr/local/lib/python3.11/site-packages/sqlalchemy/engine/default.py", line 629, in connect
    return self.loaded_dbapi.connect(*cargs, **cparams)  # type: ignore[no-any-return]  # NOQA: E501
           ^^^^^^^^^^^^^^^^^^^^^^^^^^^^^^^^^^^^^^^^^^^^
  File "/usr/local/lib/python3.11/site-packages/pymysql/connections.py", line 365, in __init__
    self.connect()
  File "/usr/local/lib/python3.11/site-packages/pymysql/connections.py", line 681, in connect
    self._request_authentication()
  File "/usr/local/lib/python3.11/site-packages/pymysql/connections.py", line 980, in _request_authentication
    auth_packet = _auth.caching_sha2_password_auth(self, auth_packet)
                  ^^^^^^^^^^^^^^^^^^^^^^^^^^^^^^^^^^^^^^^^^^^^^^^^^^^
  File "/usr/local/lib/python3.11/site-packages/pymysql/_auth.py", line 271, in caching_sha2_password_auth
    data = sha2_rsa_encrypt(conn.password, conn.salt, conn.server_public_key)
           ^^^^^^^^^^^^^^^^^^^^^^^^^^^^^^^^^^^^^^^^^^^^^^^^^^^^^^^^^^^^^^^^^^
  File "/usr/local/lib/python3.11/site-packages/pymysql/_auth.py", line 144, in sha2_rsa_encrypt
    raise RuntimeError(
RuntimeError: 'cryptography' package is required for sha256_password or caching_sha2_password auth methods
2025-08-28 09:32:51 | ERROR    | phase1_sync | MySQL 連接失敗：'cryptography' package is required for sha256_password or caching_sha2_password auth methods
2025-08-28 09:32:51 | ERROR    | phase1_sync | 程式發生嚴重錯誤：'cryptography' package is required for sha256_password or caching_sha2_password auth methods
Traceback (most recent call last):
  File "/app/scripts/phase1/main.py", line 407, in main
    syncer = CrossTableSync()
             ^^^^^^^^^^^^^^^^
  File "/app/scripts/phase1/main.py", line 52, in __init__
    self.mysql = MySQLConnector(self.db_config['mysql'], logger)
                 ^^^^^^^^^^^^^^^^^^^^^^^^^^^^^^^^^^^^^^^^^^^^^^^
  File "/app/scripts/phase1/mysql_connector.py", line 30, in __init__
    self._init_connection()
  File "/app/scripts/phase1/mysql_connector.py", line 55, in _init_connection
    with self.engine.connect() as conn:
         ^^^^^^^^^^^^^^^^^^^^^
  File "/usr/local/lib/python3.11/site-packages/sqlalchemy/engine/base.py", line 3277, in connect
    return self._connection_cls(self)
           ^^^^^^^^^^^^^^^^^^^^^^^^^^
  File "/usr/local/lib/python3.11/site-packages/sqlalchemy/engine/base.py", line 143, in __init__
    self._dbapi_connection = engine.raw_connection()
                             ^^^^^^^^^^^^^^^^^^^^^^^
  File "/usr/local/lib/python3.11/site-packages/sqlalchemy/engine/base.py", line 3301, in raw_connection
    return self.pool.connect()
           ^^^^^^^^^^^^^^^^^^^
  File "/usr/local/lib/python3.11/site-packages/sqlalchemy/pool/base.py", line 447, in connect
    return _ConnectionFairy._checkout(self)
           ^^^^^^^^^^^^^^^^^^^^^^^^^^^^^^^^
  File "/usr/local/lib/python3.11/site-packages/sqlalchemy/pool/base.py", line 1264, in _checkout
    fairy = _ConnectionRecord.checkout(pool)
            ^^^^^^^^^^^^^^^^^^^^^^^^^^^^^^^^
  File "/usr/local/lib/python3.11/site-packages/sqlalchemy/pool/base.py", line 711, in checkout
    rec = pool._do_get()
          ^^^^^^^^^^^^^^
  File "/usr/local/lib/python3.11/site-packages/sqlalchemy/pool/impl.py", line 177, in _do_get
    with util.safe_reraise():
  File "/usr/local/lib/python3.11/site-packages/sqlalchemy/util/langhelpers.py", line 224, in __exit__
    raise exc_value.with_traceback(exc_tb)
  File "/usr/local/lib/python3.11/site-packages/sqlalchemy/pool/impl.py", line 175, in _do_get
    return self._create_connection()
           ^^^^^^^^^^^^^^^^^^^^^^^^^
  File "/usr/local/lib/python3.11/site-packages/sqlalchemy/pool/base.py", line 388, in _create_connection
    return _ConnectionRecord(self)
           ^^^^^^^^^^^^^^^^^^^^^^^
  File "/usr/local/lib/python3.11/site-packages/sqlalchemy/pool/base.py", line 673, in __init__
    self.__connect()
  File "/usr/local/lib/python3.11/site-packages/sqlalchemy/pool/base.py", line 899, in __connect
    with util.safe_reraise():
  File "/usr/local/lib/python3.11/site-packages/sqlalchemy/util/langhelpers.py", line 224, in __exit__
    raise exc_value.with_traceback(exc_tb)
  File "/usr/local/lib/python3.11/site-packages/sqlalchemy/pool/base.py", line 895, in __connect
    self.dbapi_connection = connection = pool._invoke_creator(self)
                                         ^^^^^^^^^^^^^^^^^^^^^^^^^^
  File "/usr/local/lib/python3.11/site-packages/sqlalchemy/engine/create.py", line 661, in connect
    return dialect.connect(*cargs, **cparams)
           ^^^^^^^^^^^^^^^^^^^^^^^^^^^^^^^^^^
  File "/usr/local/lib/python3.11/site-packages/sqlalchemy/engine/default.py", line 629, in connect
    return self.loaded_dbapi.connect(*cargs, **cparams)  # type: ignore[no-any-return]  # NOQA: E501
           ^^^^^^^^^^^^^^^^^^^^^^^^^^^^^^^^^^^^^^^^^^^^
  File "/usr/local/lib/python3.11/site-packages/pymysql/connections.py", line 365, in __init__
    self.connect()
  File "/usr/local/lib/python3.11/site-packages/pymysql/connections.py", line 681, in connect
    self._request_authentication()
  File "/usr/local/lib/python3.11/site-packages/pymysql/connections.py", line 980, in _request_authentication
    auth_packet = _auth.caching_sha2_password_auth(self, auth_packet)
                  ^^^^^^^^^^^^^^^^^^^^^^^^^^^^^^^^^^^^^^^^^^^^^^^^^^^
  File "/usr/local/lib/python3.11/site-packages/pymysql/_auth.py", line 271, in caching_sha2_password_auth
    data = sha2_rsa_encrypt(conn.password, conn.salt, conn.server_public_key)
           ^^^^^^^^^^^^^^^^^^^^^^^^^^^^^^^^^^^^^^^^^^^^^^^^^^^^^^^^^^^^^^^^^^
  File "/usr/local/lib/python3.11/site-packages/pymysql/_auth.py", line 144, in sha2_rsa_encrypt
    raise RuntimeError(
RuntimeError: 'cryptography' package is required for sha256_password or caching_sha2_password auth methods
2025-08-28 09:32:55 | ERROR    | phase1_sync | MySQL 連接失敗：'cryptography' package is required for sha256_password or caching_sha2_password auth methods
2025-08-28 09:32:55 | ERROR    | phase1_sync | 程式發生嚴重錯誤：'cryptography' package is required for sha256_password or caching_sha2_password auth methods
Traceback (most recent call last):
  File "/app/scripts/phase1/main.py", line 407, in main
    syncer = CrossTableSync()
             ^^^^^^^^^^^^^^^^
  File "/app/scripts/phase1/main.py", line 52, in __init__
    self.mysql = MySQLConnector(self.db_config['mysql'], logger)
                 ^^^^^^^^^^^^^^^^^^^^^^^^^^^^^^^^^^^^^^^^^^^^^^^
  File "/app/scripts/phase1/mysql_connector.py", line 30, in __init__
    self._init_connection()
  File "/app/scripts/phase1/mysql_connector.py", line 55, in _init_connection
    with self.engine.connect() as conn:
         ^^^^^^^^^^^^^^^^^^^^^
  File "/usr/local/lib/python3.11/site-packages/sqlalchemy/engine/base.py", line 3277, in connect
    return self._connection_cls(self)
           ^^^^^^^^^^^^^^^^^^^^^^^^^^
  File "/usr/local/lib/python3.11/site-packages/sqlalchemy/engine/base.py", line 143, in __init__
    self._dbapi_connection = engine.raw_connection()
                             ^^^^^^^^^^^^^^^^^^^^^^^
  File "/usr/local/lib/python3.11/site-packages/sqlalchemy/engine/base.py", line 3301, in raw_connection
    return self.pool.connect()
           ^^^^^^^^^^^^^^^^^^^
  File "/usr/local/lib/python3.11/site-packages/sqlalchemy/pool/base.py", line 447, in connect
    return _ConnectionFairy._checkout(self)
           ^^^^^^^^^^^^^^^^^^^^^^^^^^^^^^^^
  File "/usr/local/lib/python3.11/site-packages/sqlalchemy/pool/base.py", line 1264, in _checkout
    fairy = _ConnectionRecord.checkout(pool)
            ^^^^^^^^^^^^^^^^^^^^^^^^^^^^^^^^
  File "/usr/local/lib/python3.11/site-packages/sqlalchemy/pool/base.py", line 711, in checkout
    rec = pool._do_get()
          ^^^^^^^^^^^^^^
  File "/usr/local/lib/python3.11/site-packages/sqlalchemy/pool/impl.py", line 177, in _do_get
    with util.safe_reraise():
  File "/usr/local/lib/python3.11/site-packages/sqlalchemy/util/langhelpers.py", line 224, in __exit__
    raise exc_value.with_traceback(exc_tb)
  File "/usr/local/lib/python3.11/site-packages/sqlalchemy/pool/impl.py", line 175, in _do_get
    return self._create_connection()
           ^^^^^^^^^^^^^^^^^^^^^^^^^
  File "/usr/local/lib/python3.11/site-packages/sqlalchemy/pool/base.py", line 388, in _create_connection
    return _ConnectionRecord(self)
           ^^^^^^^^^^^^^^^^^^^^^^^
  File "/usr/local/lib/python3.11/site-packages/sqlalchemy/pool/base.py", line 673, in __init__
    self.__connect()
  File "/usr/local/lib/python3.11/site-packages/sqlalchemy/pool/base.py", line 899, in __connect
    with util.safe_reraise():
  File "/usr/local/lib/python3.11/site-packages/sqlalchemy/util/langhelpers.py", line 224, in __exit__
    raise exc_value.with_traceback(exc_tb)
  File "/usr/local/lib/python3.11/site-packages/sqlalchemy/pool/base.py", line 895, in __connect
    self.dbapi_connection = connection = pool._invoke_creator(self)
                                         ^^^^^^^^^^^^^^^^^^^^^^^^^^
  File "/usr/local/lib/python3.11/site-packages/sqlalchemy/engine/create.py", line 661, in connect
    return dialect.connect(*cargs, **cparams)
           ^^^^^^^^^^^^^^^^^^^^^^^^^^^^^^^^^^
  File "/usr/local/lib/python3.11/site-packages/sqlalchemy/engine/default.py", line 629, in connect
    return self.loaded_dbapi.connect(*cargs, **cparams)  # type: ignore[no-any-return]  # NOQA: E501
           ^^^^^^^^^^^^^^^^^^^^^^^^^^^^^^^^^^^^^^^^^^^^
  File "/usr/local/lib/python3.11/site-packages/pymysql/connections.py", line 365, in __init__
    self.connect()
  File "/usr/local/lib/python3.11/site-packages/pymysql/connections.py", line 681, in connect
    self._request_authentication()
  File "/usr/local/lib/python3.11/site-packages/pymysql/connections.py", line 980, in _request_authentication
    auth_packet = _auth.caching_sha2_password_auth(self, auth_packet)
                  ^^^^^^^^^^^^^^^^^^^^^^^^^^^^^^^^^^^^^^^^^^^^^^^^^^^
  File "/usr/local/lib/python3.11/site-packages/pymysql/_auth.py", line 271, in caching_sha2_password_auth
    data = sha2_rsa_encrypt(conn.password, conn.salt, conn.server_public_key)
           ^^^^^^^^^^^^^^^^^^^^^^^^^^^^^^^^^^^^^^^^^^^^^^^^^^^^^^^^^^^^^^^^^^
  File "/usr/local/lib/python3.11/site-packages/pymysql/_auth.py", line 144, in sha2_rsa_encrypt
    raise RuntimeError(
RuntimeError: 'cryptography' package is required for sha256_password or caching_sha2_password auth methods
2025-08-28 09:43:44 | ERROR    | phase1_sync | MySQL 連接失敗：'cryptography' package is required for sha256_password or caching_sha2_password auth methods
2025-08-28 09:43:44 | ERROR    | phase1_sync | 程式發生嚴重錯誤：'cryptography' package is required for sha256_password or caching_sha2_password auth methods
Traceback (most recent call last):
  File "/app/scripts/phase1/main.py", line 407, in main
    syncer = CrossTableSync()
             ^^^^^^^^^^^^^^^^
  File "/app/scripts/phase1/main.py", line 52, in __init__
    self.mysql = MySQLConnector(self.db_config['mysql'], logger)
                 ^^^^^^^^^^^^^^^^^^^^^^^^^^^^^^^^^^^^^^^^^^^^^^^
  File "/app/scripts/phase1/mysql_connector.py", line 30, in __init__
    self._init_connection()
  File "/app/scripts/phase1/mysql_connector.py", line 55, in _init_connection
    with self.engine.connect() as conn:
         ^^^^^^^^^^^^^^^^^^^^^
  File "/usr/local/lib/python3.11/site-packages/sqlalchemy/engine/base.py", line 3277, in connect
    return self._connection_cls(self)
           ^^^^^^^^^^^^^^^^^^^^^^^^^^
  File "/usr/local/lib/python3.11/site-packages/sqlalchemy/engine/base.py", line 143, in __init__
    self._dbapi_connection = engine.raw_connection()
                             ^^^^^^^^^^^^^^^^^^^^^^^
  File "/usr/local/lib/python3.11/site-packages/sqlalchemy/engine/base.py", line 3301, in raw_connection
    return self.pool.connect()
           ^^^^^^^^^^^^^^^^^^^
  File "/usr/local/lib/python3.11/site-packages/sqlalchemy/pool/base.py", line 447, in connect
    return _ConnectionFairy._checkout(self)
           ^^^^^^^^^^^^^^^^^^^^^^^^^^^^^^^^
  File "/usr/local/lib/python3.11/site-packages/sqlalchemy/pool/base.py", line 1264, in _checkout
    fairy = _ConnectionRecord.checkout(pool)
            ^^^^^^^^^^^^^^^^^^^^^^^^^^^^^^^^
  File "/usr/local/lib/python3.11/site-packages/sqlalchemy/pool/base.py", line 711, in checkout
    rec = pool._do_get()
          ^^^^^^^^^^^^^^
  File "/usr/local/lib/python3.11/site-packages/sqlalchemy/pool/impl.py", line 177, in _do_get
    with util.safe_reraise():
  File "/usr/local/lib/python3.11/site-packages/sqlalchemy/util/langhelpers.py", line 224, in __exit__
    raise exc_value.with_traceback(exc_tb)
  File "/usr/local/lib/python3.11/site-packages/sqlalchemy/pool/impl.py", line 175, in _do_get
    return self._create_connection()
           ^^^^^^^^^^^^^^^^^^^^^^^^^
  File "/usr/local/lib/python3.11/site-packages/sqlalchemy/pool/base.py", line 388, in _create_connection
    return _ConnectionRecord(self)
           ^^^^^^^^^^^^^^^^^^^^^^^
  File "/usr/local/lib/python3.11/site-packages/sqlalchemy/pool/base.py", line 673, in __init__
    self.__connect()
  File "/usr/local/lib/python3.11/site-packages/sqlalchemy/pool/base.py", line 899, in __connect
    with util.safe_reraise():
  File "/usr/local/lib/python3.11/site-packages/sqlalchemy/util/langhelpers.py", line 224, in __exit__
    raise exc_value.with_traceback(exc_tb)
  File "/usr/local/lib/python3.11/site-packages/sqlalchemy/pool/base.py", line 895, in __connect
    self.dbapi_connection = connection = pool._invoke_creator(self)
                                         ^^^^^^^^^^^^^^^^^^^^^^^^^^
  File "/usr/local/lib/python3.11/site-packages/sqlalchemy/engine/create.py", line 661, in connect
    return dialect.connect(*cargs, **cparams)
           ^^^^^^^^^^^^^^^^^^^^^^^^^^^^^^^^^^
  File "/usr/local/lib/python3.11/site-packages/sqlalchemy/engine/default.py", line 629, in connect
    return self.loaded_dbapi.connect(*cargs, **cparams)  # type: ignore[no-any-return]  # NOQA: E501
           ^^^^^^^^^^^^^^^^^^^^^^^^^^^^^^^^^^^^^^^^^^^^
  File "/usr/local/lib/python3.11/site-packages/pymysql/connections.py", line 365, in __init__
    self.connect()
  File "/usr/local/lib/python3.11/site-packages/pymysql/connections.py", line 681, in connect
    self._request_authentication()
  File "/usr/local/lib/python3.11/site-packages/pymysql/connections.py", line 980, in _request_authentication
    auth_packet = _auth.caching_sha2_password_auth(self, auth_packet)
                  ^^^^^^^^^^^^^^^^^^^^^^^^^^^^^^^^^^^^^^^^^^^^^^^^^^^
  File "/usr/local/lib/python3.11/site-packages/pymysql/_auth.py", line 271, in caching_sha2_password_auth
    data = sha2_rsa_encrypt(conn.password, conn.salt, conn.server_public_key)
           ^^^^^^^^^^^^^^^^^^^^^^^^^^^^^^^^^^^^^^^^^^^^^^^^^^^^^^^^^^^^^^^^^^
  File "/usr/local/lib/python3.11/site-packages/pymysql/_auth.py", line 144, in sha2_rsa_encrypt
    raise RuntimeError(
RuntimeError: 'cryptography' package is required for sha256_password or caching_sha2_password auth methods
2025-08-28 09:43:45 | ERROR    | phase1_sync | MySQL 連接失敗：'cryptography' package is required for sha256_password or caching_sha2_password auth methods
2025-08-28 09:43:45 | ERROR    | phase1_sync | 程式發生嚴重錯誤：'cryptography' package is required for sha256_password or caching_sha2_password auth methods
Traceback (most recent call last):
  File "/app/scripts/phase1/main.py", line 407, in main
    syncer = CrossTableSync()
             ^^^^^^^^^^^^^^^^
  File "/app/scripts/phase1/main.py", line 52, in __init__
    self.mysql = MySQLConnector(self.db_config['mysql'], logger)
                 ^^^^^^^^^^^^^^^^^^^^^^^^^^^^^^^^^^^^^^^^^^^^^^^
  File "/app/scripts/phase1/mysql_connector.py", line 30, in __init__
    self._init_connection()
  File "/app/scripts/phase1/mysql_connector.py", line 55, in _init_connection
    with self.engine.connect() as conn:
         ^^^^^^^^^^^^^^^^^^^^^
  File "/usr/local/lib/python3.11/site-packages/sqlalchemy/engine/base.py", line 3277, in connect
    return self._connection_cls(self)
           ^^^^^^^^^^^^^^^^^^^^^^^^^^
  File "/usr/local/lib/python3.11/site-packages/sqlalchemy/engine/base.py", line 143, in __init__
    self._dbapi_connection = engine.raw_connection()
                             ^^^^^^^^^^^^^^^^^^^^^^^
  File "/usr/local/lib/python3.11/site-packages/sqlalchemy/engine/base.py", line 3301, in raw_connection
    return self.pool.connect()
           ^^^^^^^^^^^^^^^^^^^
  File "/usr/local/lib/python3.11/site-packages/sqlalchemy/pool/base.py", line 447, in connect
    return _ConnectionFairy._checkout(self)
           ^^^^^^^^^^^^^^^^^^^^^^^^^^^^^^^^
  File "/usr/local/lib/python3.11/site-packages/sqlalchemy/pool/base.py", line 1264, in _checkout
    fairy = _ConnectionRecord.checkout(pool)
            ^^^^^^^^^^^^^^^^^^^^^^^^^^^^^^^^
  File "/usr/local/lib/python3.11/site-packages/sqlalchemy/pool/base.py", line 711, in checkout
    rec = pool._do_get()
          ^^^^^^^^^^^^^^
  File "/usr/local/lib/python3.11/site-packages/sqlalchemy/pool/impl.py", line 177, in _do_get
    with util.safe_reraise():
  File "/usr/local/lib/python3.11/site-packages/sqlalchemy/util/langhelpers.py", line 224, in __exit__
    raise exc_value.with_traceback(exc_tb)
  File "/usr/local/lib/python3.11/site-packages/sqlalchemy/pool/impl.py", line 175, in _do_get
    return self._create_connection()
           ^^^^^^^^^^^^^^^^^^^^^^^^^
  File "/usr/local/lib/python3.11/site-packages/sqlalchemy/pool/base.py", line 388, in _create_connection
    return _ConnectionRecord(self)
           ^^^^^^^^^^^^^^^^^^^^^^^
  File "/usr/local/lib/python3.11/site-packages/sqlalchemy/pool/base.py", line 673, in __init__
    self.__connect()
  File "/usr/local/lib/python3.11/site-packages/sqlalchemy/pool/base.py", line 899, in __connect
    with util.safe_reraise():
  File "/usr/local/lib/python3.11/site-packages/sqlalchemy/util/langhelpers.py", line 224, in __exit__
    raise exc_value.with_traceback(exc_tb)
  File "/usr/local/lib/python3.11/site-packages/sqlalchemy/pool/base.py", line 895, in __connect
    self.dbapi_connection = connection = pool._invoke_creator(self)
                                         ^^^^^^^^^^^^^^^^^^^^^^^^^^
  File "/usr/local/lib/python3.11/site-packages/sqlalchemy/engine/create.py", line 661, in connect
    return dialect.connect(*cargs, **cparams)
           ^^^^^^^^^^^^^^^^^^^^^^^^^^^^^^^^^^
  File "/usr/local/lib/python3.11/site-packages/sqlalchemy/engine/default.py", line 629, in connect
    return self.loaded_dbapi.connect(*cargs, **cparams)  # type: ignore[no-any-return]  # NOQA: E501
           ^^^^^^^^^^^^^^^^^^^^^^^^^^^^^^^^^^^^^^^^^^^^
  File "/usr/local/lib/python3.11/site-packages/pymysql/connections.py", line 365, in __init__
    self.connect()
  File "/usr/local/lib/python3.11/site-packages/pymysql/connections.py", line 681, in connect
    self._request_authentication()
  File "/usr/local/lib/python3.11/site-packages/pymysql/connections.py", line 980, in _request_authentication
    auth_packet = _auth.caching_sha2_password_auth(self, auth_packet)
                  ^^^^^^^^^^^^^^^^^^^^^^^^^^^^^^^^^^^^^^^^^^^^^^^^^^^
  File "/usr/local/lib/python3.11/site-packages/pymysql/_auth.py", line 271, in caching_sha2_password_auth
    data = sha2_rsa_encrypt(conn.password, conn.salt, conn.server_public_key)
           ^^^^^^^^^^^^^^^^^^^^^^^^^^^^^^^^^^^^^^^^^^^^^^^^^^^^^^^^^^^^^^^^^^
  File "/usr/local/lib/python3.11/site-packages/pymysql/_auth.py", line 144, in sha2_rsa_encrypt
    raise RuntimeError(
RuntimeError: 'cryptography' package is required for sha256_password or caching_sha2_password auth methods
2025-08-28 09:43:47 | ERROR    | phase1_sync | MySQL 連接失敗：'cryptography' package is required for sha256_password or caching_sha2_password auth methods
2025-08-28 09:43:47 | ERROR    | phase1_sync | 程式發生嚴重錯誤：'cryptography' package is required for sha256_password or caching_sha2_password auth methods
Traceback (most recent call last):
  File "/app/scripts/phase1/main.py", line 407, in main
    syncer = CrossTableSync()
             ^^^^^^^^^^^^^^^^
  File "/app/scripts/phase1/main.py", line 52, in __init__
    self.mysql = MySQLConnector(self.db_config['mysql'], logger)
                 ^^^^^^^^^^^^^^^^^^^^^^^^^^^^^^^^^^^^^^^^^^^^^^^
  File "/app/scripts/phase1/mysql_connector.py", line 30, in __init__
    self._init_connection()
  File "/app/scripts/phase1/mysql_connector.py", line 55, in _init_connection
    with self.engine.connect() as conn:
         ^^^^^^^^^^^^^^^^^^^^^
  File "/usr/local/lib/python3.11/site-packages/sqlalchemy/engine/base.py", line 3277, in connect
    return self._connection_cls(self)
           ^^^^^^^^^^^^^^^^^^^^^^^^^^
  File "/usr/local/lib/python3.11/site-packages/sqlalchemy/engine/base.py", line 143, in __init__
    self._dbapi_connection = engine.raw_connection()
                             ^^^^^^^^^^^^^^^^^^^^^^^
  File "/usr/local/lib/python3.11/site-packages/sqlalchemy/engine/base.py", line 3301, in raw_connection
    return self.pool.connect()
           ^^^^^^^^^^^^^^^^^^^
  File "/usr/local/lib/python3.11/site-packages/sqlalchemy/pool/base.py", line 447, in connect
    return _ConnectionFairy._checkout(self)
           ^^^^^^^^^^^^^^^^^^^^^^^^^^^^^^^^
  File "/usr/local/lib/python3.11/site-packages/sqlalchemy/pool/base.py", line 1264, in _checkout
    fairy = _ConnectionRecord.checkout(pool)
            ^^^^^^^^^^^^^^^^^^^^^^^^^^^^^^^^
  File "/usr/local/lib/python3.11/site-packages/sqlalchemy/pool/base.py", line 711, in checkout
    rec = pool._do_get()
          ^^^^^^^^^^^^^^
  File "/usr/local/lib/python3.11/site-packages/sqlalchemy/pool/impl.py", line 177, in _do_get
    with util.safe_reraise():
  File "/usr/local/lib/python3.11/site-packages/sqlalchemy/util/langhelpers.py", line 224, in __exit__
    raise exc_value.with_traceback(exc_tb)
  File "/usr/local/lib/python3.11/site-packages/sqlalchemy/pool/impl.py", line 175, in _do_get
    return self._create_connection()
           ^^^^^^^^^^^^^^^^^^^^^^^^^
  File "/usr/local/lib/python3.11/site-packages/sqlalchemy/pool/base.py", line 388, in _create_connection
    return _ConnectionRecord(self)
           ^^^^^^^^^^^^^^^^^^^^^^^
  File "/usr/local/lib/python3.11/site-packages/sqlalchemy/pool/base.py", line 673, in __init__
    self.__connect()
  File "/usr/local/lib/python3.11/site-packages/sqlalchemy/pool/base.py", line 899, in __connect
    with util.safe_reraise():
  File "/usr/local/lib/python3.11/site-packages/sqlalchemy/util/langhelpers.py", line 224, in __exit__
    raise exc_value.with_traceback(exc_tb)
  File "/usr/local/lib/python3.11/site-packages/sqlalchemy/pool/base.py", line 895, in __connect
    self.dbapi_connection = connection = pool._invoke_creator(self)
                                         ^^^^^^^^^^^^^^^^^^^^^^^^^^
  File "/usr/local/lib/python3.11/site-packages/sqlalchemy/engine/create.py", line 661, in connect
    return dialect.connect(*cargs, **cparams)
           ^^^^^^^^^^^^^^^^^^^^^^^^^^^^^^^^^^
  File "/usr/local/lib/python3.11/site-packages/sqlalchemy/engine/default.py", line 629, in connect
    return self.loaded_dbapi.connect(*cargs, **cparams)  # type: ignore[no-any-return]  # NOQA: E501
           ^^^^^^^^^^^^^^^^^^^^^^^^^^^^^^^^^^^^^^^^^^^^
  File "/usr/local/lib/python3.11/site-packages/pymysql/connections.py", line 365, in __init__
    self.connect()
  File "/usr/local/lib/python3.11/site-packages/pymysql/connections.py", line 681, in connect
    self._request_authentication()
  File "/usr/local/lib/python3.11/site-packages/pymysql/connections.py", line 980, in _request_authentication
    auth_packet = _auth.caching_sha2_password_auth(self, auth_packet)
                  ^^^^^^^^^^^^^^^^^^^^^^^^^^^^^^^^^^^^^^^^^^^^^^^^^^^
  File "/usr/local/lib/python3.11/site-packages/pymysql/_auth.py", line 271, in caching_sha2_password_auth
    data = sha2_rsa_encrypt(conn.password, conn.salt, conn.server_public_key)
           ^^^^^^^^^^^^^^^^^^^^^^^^^^^^^^^^^^^^^^^^^^^^^^^^^^^^^^^^^^^^^^^^^^
  File "/usr/local/lib/python3.11/site-packages/pymysql/_auth.py", line 144, in sha2_rsa_encrypt
    raise RuntimeError(
RuntimeError: 'cryptography' package is required for sha256_password or caching_sha2_password auth methods
2025-08-28 09:43:48 | ERROR    | phase1_sync | MySQL 連接失敗：'cryptography' package is required for sha256_password or caching_sha2_password auth methods
2025-08-28 09:43:48 | ERROR    | phase1_sync | 程式發生嚴重錯誤：'cryptography' package is required for sha256_password or caching_sha2_password auth methods
Traceback (most recent call last):
  File "/app/scripts/phase1/main.py", line 407, in main
    syncer = CrossTableSync()
             ^^^^^^^^^^^^^^^^
  File "/app/scripts/phase1/main.py", line 52, in __init__
    self.mysql = MySQLConnector(self.db_config['mysql'], logger)
                 ^^^^^^^^^^^^^^^^^^^^^^^^^^^^^^^^^^^^^^^^^^^^^^^
  File "/app/scripts/phase1/mysql_connector.py", line 30, in __init__
    self._init_connection()
  File "/app/scripts/phase1/mysql_connector.py", line 55, in _init_connection
    with self.engine.connect() as conn:
         ^^^^^^^^^^^^^^^^^^^^^
  File "/usr/local/lib/python3.11/site-packages/sqlalchemy/engine/base.py", line 3277, in connect
    return self._connection_cls(self)
           ^^^^^^^^^^^^^^^^^^^^^^^^^^
  File "/usr/local/lib/python3.11/site-packages/sqlalchemy/engine/base.py", line 143, in __init__
    self._dbapi_connection = engine.raw_connection()
                             ^^^^^^^^^^^^^^^^^^^^^^^
  File "/usr/local/lib/python3.11/site-packages/sqlalchemy/engine/base.py", line 3301, in raw_connection
    return self.pool.connect()
           ^^^^^^^^^^^^^^^^^^^
  File "/usr/local/lib/python3.11/site-packages/sqlalchemy/pool/base.py", line 447, in connect
    return _ConnectionFairy._checkout(self)
           ^^^^^^^^^^^^^^^^^^^^^^^^^^^^^^^^
  File "/usr/local/lib/python3.11/site-packages/sqlalchemy/pool/base.py", line 1264, in _checkout
    fairy = _ConnectionRecord.checkout(pool)
            ^^^^^^^^^^^^^^^^^^^^^^^^^^^^^^^^
  File "/usr/local/lib/python3.11/site-packages/sqlalchemy/pool/base.py", line 711, in checkout
    rec = pool._do_get()
          ^^^^^^^^^^^^^^
  File "/usr/local/lib/python3.11/site-packages/sqlalchemy/pool/impl.py", line 177, in _do_get
    with util.safe_reraise():
  File "/usr/local/lib/python3.11/site-packages/sqlalchemy/util/langhelpers.py", line 224, in __exit__
    raise exc_value.with_traceback(exc_tb)
  File "/usr/local/lib/python3.11/site-packages/sqlalchemy/pool/impl.py", line 175, in _do_get
    return self._create_connection()
           ^^^^^^^^^^^^^^^^^^^^^^^^^
  File "/usr/local/lib/python3.11/site-packages/sqlalchemy/pool/base.py", line 388, in _create_connection
    return _ConnectionRecord(self)
           ^^^^^^^^^^^^^^^^^^^^^^^
  File "/usr/local/lib/python3.11/site-packages/sqlalchemy/pool/base.py", line 673, in __init__
    self.__connect()
  File "/usr/local/lib/python3.11/site-packages/sqlalchemy/pool/base.py", line 899, in __connect
    with util.safe_reraise():
  File "/usr/local/lib/python3.11/site-packages/sqlalchemy/util/langhelpers.py", line 224, in __exit__
    raise exc_value.with_traceback(exc_tb)
  File "/usr/local/lib/python3.11/site-packages/sqlalchemy/pool/base.py", line 895, in __connect
    self.dbapi_connection = connection = pool._invoke_creator(self)
                                         ^^^^^^^^^^^^^^^^^^^^^^^^^^
  File "/usr/local/lib/python3.11/site-packages/sqlalchemy/engine/create.py", line 661, in connect
    return dialect.connect(*cargs, **cparams)
           ^^^^^^^^^^^^^^^^^^^^^^^^^^^^^^^^^^
  File "/usr/local/lib/python3.11/site-packages/sqlalchemy/engine/default.py", line 629, in connect
    return self.loaded_dbapi.connect(*cargs, **cparams)  # type: ignore[no-any-return]  # NOQA: E501
           ^^^^^^^^^^^^^^^^^^^^^^^^^^^^^^^^^^^^^^^^^^^^
  File "/usr/local/lib/python3.11/site-packages/pymysql/connections.py", line 365, in __init__
    self.connect()
  File "/usr/local/lib/python3.11/site-packages/pymysql/connections.py", line 681, in connect
    self._request_authentication()
  File "/usr/local/lib/python3.11/site-packages/pymysql/connections.py", line 980, in _request_authentication
    auth_packet = _auth.caching_sha2_password_auth(self, auth_packet)
                  ^^^^^^^^^^^^^^^^^^^^^^^^^^^^^^^^^^^^^^^^^^^^^^^^^^^
  File "/usr/local/lib/python3.11/site-packages/pymysql/_auth.py", line 271, in caching_sha2_password_auth
    data = sha2_rsa_encrypt(conn.password, conn.salt, conn.server_public_key)
           ^^^^^^^^^^^^^^^^^^^^^^^^^^^^^^^^^^^^^^^^^^^^^^^^^^^^^^^^^^^^^^^^^^
  File "/usr/local/lib/python3.11/site-packages/pymysql/_auth.py", line 144, in sha2_rsa_encrypt
    raise RuntimeError(
RuntimeError: 'cryptography' package is required for sha256_password or caching_sha2_password auth methods
2025-08-28 09:43:50 | ERROR    | phase1_sync | MySQL 連接失敗：'cryptography' package is required for sha256_password or caching_sha2_password auth methods
2025-08-28 09:43:50 | ERROR    | phase1_sync | 程式發生嚴重錯誤：'cryptography' package is required for sha256_password or caching_sha2_password auth methods
Traceback (most recent call last):
  File "/app/scripts/phase1/main.py", line 407, in main
    syncer = CrossTableSync()
             ^^^^^^^^^^^^^^^^
  File "/app/scripts/phase1/main.py", line 52, in __init__
    self.mysql = MySQLConnector(self.db_config['mysql'], logger)
                 ^^^^^^^^^^^^^^^^^^^^^^^^^^^^^^^^^^^^^^^^^^^^^^^
  File "/app/scripts/phase1/mysql_connector.py", line 30, in __init__
    self._init_connection()
  File "/app/scripts/phase1/mysql_connector.py", line 55, in _init_connection
    with self.engine.connect() as conn:
         ^^^^^^^^^^^^^^^^^^^^^
  File "/usr/local/lib/python3.11/site-packages/sqlalchemy/engine/base.py", line 3277, in connect
    return self._connection_cls(self)
           ^^^^^^^^^^^^^^^^^^^^^^^^^^
  File "/usr/local/lib/python3.11/site-packages/sqlalchemy/engine/base.py", line 143, in __init__
    self._dbapi_connection = engine.raw_connection()
                             ^^^^^^^^^^^^^^^^^^^^^^^
  File "/usr/local/lib/python3.11/site-packages/sqlalchemy/engine/base.py", line 3301, in raw_connection
    return self.pool.connect()
           ^^^^^^^^^^^^^^^^^^^
  File "/usr/local/lib/python3.11/site-packages/sqlalchemy/pool/base.py", line 447, in connect
    return _ConnectionFairy._checkout(self)
           ^^^^^^^^^^^^^^^^^^^^^^^^^^^^^^^^
  File "/usr/local/lib/python3.11/site-packages/sqlalchemy/pool/base.py", line 1264, in _checkout
    fairy = _ConnectionRecord.checkout(pool)
            ^^^^^^^^^^^^^^^^^^^^^^^^^^^^^^^^
  File "/usr/local/lib/python3.11/site-packages/sqlalchemy/pool/base.py", line 711, in checkout
    rec = pool._do_get()
          ^^^^^^^^^^^^^^
  File "/usr/local/lib/python3.11/site-packages/sqlalchemy/pool/impl.py", line 177, in _do_get
    with util.safe_reraise():
  File "/usr/local/lib/python3.11/site-packages/sqlalchemy/util/langhelpers.py", line 224, in __exit__
    raise exc_value.with_traceback(exc_tb)
  File "/usr/local/lib/python3.11/site-packages/sqlalchemy/pool/impl.py", line 175, in _do_get
    return self._create_connection()
           ^^^^^^^^^^^^^^^^^^^^^^^^^
  File "/usr/local/lib/python3.11/site-packages/sqlalchemy/pool/base.py", line 388, in _create_connection
    return _ConnectionRecord(self)
           ^^^^^^^^^^^^^^^^^^^^^^^
  File "/usr/local/lib/python3.11/site-packages/sqlalchemy/pool/base.py", line 673, in __init__
    self.__connect()
  File "/usr/local/lib/python3.11/site-packages/sqlalchemy/pool/base.py", line 899, in __connect
    with util.safe_reraise():
  File "/usr/local/lib/python3.11/site-packages/sqlalchemy/util/langhelpers.py", line 224, in __exit__
    raise exc_value.with_traceback(exc_tb)
  File "/usr/local/lib/python3.11/site-packages/sqlalchemy/pool/base.py", line 895, in __connect
    self.dbapi_connection = connection = pool._invoke_creator(self)
                                         ^^^^^^^^^^^^^^^^^^^^^^^^^^
  File "/usr/local/lib/python3.11/site-packages/sqlalchemy/engine/create.py", line 661, in connect
    return dialect.connect(*cargs, **cparams)
           ^^^^^^^^^^^^^^^^^^^^^^^^^^^^^^^^^^
  File "/usr/local/lib/python3.11/site-packages/sqlalchemy/engine/default.py", line 629, in connect
    return self.loaded_dbapi.connect(*cargs, **cparams)  # type: ignore[no-any-return]  # NOQA: E501
           ^^^^^^^^^^^^^^^^^^^^^^^^^^^^^^^^^^^^^^^^^^^^
  File "/usr/local/lib/python3.11/site-packages/pymysql/connections.py", line 365, in __init__
    self.connect()
  File "/usr/local/lib/python3.11/site-packages/pymysql/connections.py", line 681, in connect
    self._request_authentication()
  File "/usr/local/lib/python3.11/site-packages/pymysql/connections.py", line 980, in _request_authentication
    auth_packet = _auth.caching_sha2_password_auth(self, auth_packet)
                  ^^^^^^^^^^^^^^^^^^^^^^^^^^^^^^^^^^^^^^^^^^^^^^^^^^^
  File "/usr/local/lib/python3.11/site-packages/pymysql/_auth.py", line 271, in caching_sha2_password_auth
    data = sha2_rsa_encrypt(conn.password, conn.salt, conn.server_public_key)
           ^^^^^^^^^^^^^^^^^^^^^^^^^^^^^^^^^^^^^^^^^^^^^^^^^^^^^^^^^^^^^^^^^^
  File "/usr/local/lib/python3.11/site-packages/pymysql/_auth.py", line 144, in sha2_rsa_encrypt
    raise RuntimeError(
RuntimeError: 'cryptography' package is required for sha256_password or caching_sha2_password auth methods
2025-08-28 09:43:52 | ERROR    | phase1_sync | MySQL 連接失敗：'cryptography' package is required for sha256_password or caching_sha2_password auth methods
2025-08-28 09:43:52 | ERROR    | phase1_sync | 程式發生嚴重錯誤：'cryptography' package is required for sha256_password or caching_sha2_password auth methods
Traceback (most recent call last):
  File "/app/scripts/phase1/main.py", line 407, in main
    syncer = CrossTableSync()
             ^^^^^^^^^^^^^^^^
  File "/app/scripts/phase1/main.py", line 52, in __init__
    self.mysql = MySQLConnector(self.db_config['mysql'], logger)
                 ^^^^^^^^^^^^^^^^^^^^^^^^^^^^^^^^^^^^^^^^^^^^^^^
  File "/app/scripts/phase1/mysql_connector.py", line 30, in __init__
    self._init_connection()
  File "/app/scripts/phase1/mysql_connector.py", line 55, in _init_connection
    with self.engine.connect() as conn:
         ^^^^^^^^^^^^^^^^^^^^^
  File "/usr/local/lib/python3.11/site-packages/sqlalchemy/engine/base.py", line 3277, in connect
    return self._connection_cls(self)
           ^^^^^^^^^^^^^^^^^^^^^^^^^^
  File "/usr/local/lib/python3.11/site-packages/sqlalchemy/engine/base.py", line 143, in __init__
    self._dbapi_connection = engine.raw_connection()
                             ^^^^^^^^^^^^^^^^^^^^^^^
  File "/usr/local/lib/python3.11/site-packages/sqlalchemy/engine/base.py", line 3301, in raw_connection
    return self.pool.connect()
           ^^^^^^^^^^^^^^^^^^^
  File "/usr/local/lib/python3.11/site-packages/sqlalchemy/pool/base.py", line 447, in connect
    return _ConnectionFairy._checkout(self)
           ^^^^^^^^^^^^^^^^^^^^^^^^^^^^^^^^
  File "/usr/local/lib/python3.11/site-packages/sqlalchemy/pool/base.py", line 1264, in _checkout
    fairy = _ConnectionRecord.checkout(pool)
            ^^^^^^^^^^^^^^^^^^^^^^^^^^^^^^^^
  File "/usr/local/lib/python3.11/site-packages/sqlalchemy/pool/base.py", line 711, in checkout
    rec = pool._do_get()
          ^^^^^^^^^^^^^^
  File "/usr/local/lib/python3.11/site-packages/sqlalchemy/pool/impl.py", line 177, in _do_get
    with util.safe_reraise():
  File "/usr/local/lib/python3.11/site-packages/sqlalchemy/util/langhelpers.py", line 224, in __exit__
    raise exc_value.with_traceback(exc_tb)
  File "/usr/local/lib/python3.11/site-packages/sqlalchemy/pool/impl.py", line 175, in _do_get
    return self._create_connection()
           ^^^^^^^^^^^^^^^^^^^^^^^^^
  File "/usr/local/lib/python3.11/site-packages/sqlalchemy/pool/base.py", line 388, in _create_connection
    return _ConnectionRecord(self)
           ^^^^^^^^^^^^^^^^^^^^^^^
  File "/usr/local/lib/python3.11/site-packages/sqlalchemy/pool/base.py", line 673, in __init__
    self.__connect()
  File "/usr/local/lib/python3.11/site-packages/sqlalchemy/pool/base.py", line 899, in __connect
    with util.safe_reraise():
  File "/usr/local/lib/python3.11/site-packages/sqlalchemy/util/langhelpers.py", line 224, in __exit__
    raise exc_value.with_traceback(exc_tb)
  File "/usr/local/lib/python3.11/site-packages/sqlalchemy/pool/base.py", line 895, in __connect
    self.dbapi_connection = connection = pool._invoke_creator(self)
                                         ^^^^^^^^^^^^^^^^^^^^^^^^^^
  File "/usr/local/lib/python3.11/site-packages/sqlalchemy/engine/create.py", line 661, in connect
    return dialect.connect(*cargs, **cparams)
           ^^^^^^^^^^^^^^^^^^^^^^^^^^^^^^^^^^
  File "/usr/local/lib/python3.11/site-packages/sqlalchemy/engine/default.py", line 629, in connect
    return self.loaded_dbapi.connect(*cargs, **cparams)  # type: ignore[no-any-return]  # NOQA: E501
           ^^^^^^^^^^^^^^^^^^^^^^^^^^^^^^^^^^^^^^^^^^^^
  File "/usr/local/lib/python3.11/site-packages/pymysql/connections.py", line 365, in __init__
    self.connect()
  File "/usr/local/lib/python3.11/site-packages/pymysql/connections.py", line 681, in connect
    self._request_authentication()
  File "/usr/local/lib/python3.11/site-packages/pymysql/connections.py", line 980, in _request_authentication
    auth_packet = _auth.caching_sha2_password_auth(self, auth_packet)
                  ^^^^^^^^^^^^^^^^^^^^^^^^^^^^^^^^^^^^^^^^^^^^^^^^^^^
  File "/usr/local/lib/python3.11/site-packages/pymysql/_auth.py", line 271, in caching_sha2_password_auth
    data = sha2_rsa_encrypt(conn.password, conn.salt, conn.server_public_key)
           ^^^^^^^^^^^^^^^^^^^^^^^^^^^^^^^^^^^^^^^^^^^^^^^^^^^^^^^^^^^^^^^^^^
  File "/usr/local/lib/python3.11/site-packages/pymysql/_auth.py", line 144, in sha2_rsa_encrypt
    raise RuntimeError(
RuntimeError: 'cryptography' package is required for sha256_password or caching_sha2_password auth methods
2025-08-28 09:43:57 | ERROR    | phase1_sync | MySQL 連接失敗：'cryptography' package is required for sha256_password or caching_sha2_password auth methods
2025-08-28 09:43:57 | ERROR    | phase1_sync | 程式發生嚴重錯誤：'cryptography' package is required for sha256_password or caching_sha2_password auth methods
Traceback (most recent call last):
  File "/app/scripts/phase1/main.py", line 407, in main
    syncer = CrossTableSync()
             ^^^^^^^^^^^^^^^^
  File "/app/scripts/phase1/main.py", line 52, in __init__
    self.mysql = MySQLConnector(self.db_config['mysql'], logger)
                 ^^^^^^^^^^^^^^^^^^^^^^^^^^^^^^^^^^^^^^^^^^^^^^^
  File "/app/scripts/phase1/mysql_connector.py", line 30, in __init__
    self._init_connection()
  File "/app/scripts/phase1/mysql_connector.py", line 55, in _init_connection
    with self.engine.connect() as conn:
         ^^^^^^^^^^^^^^^^^^^^^
  File "/usr/local/lib/python3.11/site-packages/sqlalchemy/engine/base.py", line 3277, in connect
    return self._connection_cls(self)
           ^^^^^^^^^^^^^^^^^^^^^^^^^^
  File "/usr/local/lib/python3.11/site-packages/sqlalchemy/engine/base.py", line 143, in __init__
    self._dbapi_connection = engine.raw_connection()
                             ^^^^^^^^^^^^^^^^^^^^^^^
  File "/usr/local/lib/python3.11/site-packages/sqlalchemy/engine/base.py", line 3301, in raw_connection
    return self.pool.connect()
           ^^^^^^^^^^^^^^^^^^^
  File "/usr/local/lib/python3.11/site-packages/sqlalchemy/pool/base.py", line 447, in connect
    return _ConnectionFairy._checkout(self)
           ^^^^^^^^^^^^^^^^^^^^^^^^^^^^^^^^
  File "/usr/local/lib/python3.11/site-packages/sqlalchemy/pool/base.py", line 1264, in _checkout
    fairy = _ConnectionRecord.checkout(pool)
            ^^^^^^^^^^^^^^^^^^^^^^^^^^^^^^^^
  File "/usr/local/lib/python3.11/site-packages/sqlalchemy/pool/base.py", line 711, in checkout
    rec = pool._do_get()
          ^^^^^^^^^^^^^^
  File "/usr/local/lib/python3.11/site-packages/sqlalchemy/pool/impl.py", line 177, in _do_get
    with util.safe_reraise():
  File "/usr/local/lib/python3.11/site-packages/sqlalchemy/util/langhelpers.py", line 224, in __exit__
    raise exc_value.with_traceback(exc_tb)
  File "/usr/local/lib/python3.11/site-packages/sqlalchemy/pool/impl.py", line 175, in _do_get
    return self._create_connection()
           ^^^^^^^^^^^^^^^^^^^^^^^^^
  File "/usr/local/lib/python3.11/site-packages/sqlalchemy/pool/base.py", line 388, in _create_connection
    return _ConnectionRecord(self)
           ^^^^^^^^^^^^^^^^^^^^^^^
  File "/usr/local/lib/python3.11/site-packages/sqlalchemy/pool/base.py", line 673, in __init__
    self.__connect()
  File "/usr/local/lib/python3.11/site-packages/sqlalchemy/pool/base.py", line 899, in __connect
    with util.safe_reraise():
  File "/usr/local/lib/python3.11/site-packages/sqlalchemy/util/langhelpers.py", line 224, in __exit__
    raise exc_value.with_traceback(exc_tb)
  File "/usr/local/lib/python3.11/site-packages/sqlalchemy/pool/base.py", line 895, in __connect
    self.dbapi_connection = connection = pool._invoke_creator(self)
                                         ^^^^^^^^^^^^^^^^^^^^^^^^^^
  File "/usr/local/lib/python3.11/site-packages/sqlalchemy/engine/create.py", line 661, in connect
    return dialect.connect(*cargs, **cparams)
           ^^^^^^^^^^^^^^^^^^^^^^^^^^^^^^^^^^
  File "/usr/local/lib/python3.11/site-packages/sqlalchemy/engine/default.py", line 629, in connect
    return self.loaded_dbapi.connect(*cargs, **cparams)  # type: ignore[no-any-return]  # NOQA: E501
           ^^^^^^^^^^^^^^^^^^^^^^^^^^^^^^^^^^^^^^^^^^^^
  File "/usr/local/lib/python3.11/site-packages/pymysql/connections.py", line 365, in __init__
    self.connect()
  File "/usr/local/lib/python3.11/site-packages/pymysql/connections.py", line 681, in connect
    self._request_authentication()
  File "/usr/local/lib/python3.11/site-packages/pymysql/connections.py", line 980, in _request_authentication
    auth_packet = _auth.caching_sha2_password_auth(self, auth_packet)
                  ^^^^^^^^^^^^^^^^^^^^^^^^^^^^^^^^^^^^^^^^^^^^^^^^^^^
  File "/usr/local/lib/python3.11/site-packages/pymysql/_auth.py", line 271, in caching_sha2_password_auth
    data = sha2_rsa_encrypt(conn.password, conn.salt, conn.server_public_key)
           ^^^^^^^^^^^^^^^^^^^^^^^^^^^^^^^^^^^^^^^^^^^^^^^^^^^^^^^^^^^^^^^^^^
  File "/usr/local/lib/python3.11/site-packages/pymysql/_auth.py", line 144, in sha2_rsa_encrypt
    raise RuntimeError(
RuntimeError: 'cryptography' package is required for sha256_password or caching_sha2_password auth methods
2025-08-28 09:44:04 | ERROR    | phase1_sync | MySQL 連接失敗：'cryptography' package is required for sha256_password or caching_sha2_password auth methods
2025-08-28 09:44:04 | ERROR    | phase1_sync | 程式發生嚴重錯誤：'cryptography' package is required for sha256_password or caching_sha2_password auth methods
Traceback (most recent call last):
  File "/app/scripts/phase1/main.py", line 407, in main
    syncer = CrossTableSync()
             ^^^^^^^^^^^^^^^^
  File "/app/scripts/phase1/main.py", line 52, in __init__
    self.mysql = MySQLConnector(self.db_config['mysql'], logger)
                 ^^^^^^^^^^^^^^^^^^^^^^^^^^^^^^^^^^^^^^^^^^^^^^^
  File "/app/scripts/phase1/mysql_connector.py", line 30, in __init__
    self._init_connection()
  File "/app/scripts/phase1/mysql_connector.py", line 55, in _init_connection
    with self.engine.connect() as conn:
         ^^^^^^^^^^^^^^^^^^^^^
  File "/usr/local/lib/python3.11/site-packages/sqlalchemy/engine/base.py", line 3277, in connect
    return self._connection_cls(self)
           ^^^^^^^^^^^^^^^^^^^^^^^^^^
  File "/usr/local/lib/python3.11/site-packages/sqlalchemy/engine/base.py", line 143, in __init__
    self._dbapi_connection = engine.raw_connection()
                             ^^^^^^^^^^^^^^^^^^^^^^^
  File "/usr/local/lib/python3.11/site-packages/sqlalchemy/engine/base.py", line 3301, in raw_connection
    return self.pool.connect()
           ^^^^^^^^^^^^^^^^^^^
  File "/usr/local/lib/python3.11/site-packages/sqlalchemy/pool/base.py", line 447, in connect
    return _ConnectionFairy._checkout(self)
           ^^^^^^^^^^^^^^^^^^^^^^^^^^^^^^^^
  File "/usr/local/lib/python3.11/site-packages/sqlalchemy/pool/base.py", line 1264, in _checkout
    fairy = _ConnectionRecord.checkout(pool)
            ^^^^^^^^^^^^^^^^^^^^^^^^^^^^^^^^
  File "/usr/local/lib/python3.11/site-packages/sqlalchemy/pool/base.py", line 711, in checkout
    rec = pool._do_get()
          ^^^^^^^^^^^^^^
  File "/usr/local/lib/python3.11/site-packages/sqlalchemy/pool/impl.py", line 177, in _do_get
    with util.safe_reraise():
  File "/usr/local/lib/python3.11/site-packages/sqlalchemy/util/langhelpers.py", line 224, in __exit__
    raise exc_value.with_traceback(exc_tb)
  File "/usr/local/lib/python3.11/site-packages/sqlalchemy/pool/impl.py", line 175, in _do_get
    return self._create_connection()
           ^^^^^^^^^^^^^^^^^^^^^^^^^
  File "/usr/local/lib/python3.11/site-packages/sqlalchemy/pool/base.py", line 388, in _create_connection
    return _ConnectionRecord(self)
           ^^^^^^^^^^^^^^^^^^^^^^^
  File "/usr/local/lib/python3.11/site-packages/sqlalchemy/pool/base.py", line 673, in __init__
    self.__connect()
  File "/usr/local/lib/python3.11/site-packages/sqlalchemy/pool/base.py", line 899, in __connect
    with util.safe_reraise():
  File "/usr/local/lib/python3.11/site-packages/sqlalchemy/util/langhelpers.py", line 224, in __exit__
    raise exc_value.with_traceback(exc_tb)
  File "/usr/local/lib/python3.11/site-packages/sqlalchemy/pool/base.py", line 895, in __connect
    self.dbapi_connection = connection = pool._invoke_creator(self)
                                         ^^^^^^^^^^^^^^^^^^^^^^^^^^
  File "/usr/local/lib/python3.11/site-packages/sqlalchemy/engine/create.py", line 661, in connect
    return dialect.connect(*cargs, **cparams)
           ^^^^^^^^^^^^^^^^^^^^^^^^^^^^^^^^^^
  File "/usr/local/lib/python3.11/site-packages/sqlalchemy/engine/default.py", line 629, in connect
    return self.loaded_dbapi.connect(*cargs, **cparams)  # type: ignore[no-any-return]  # NOQA: E501
           ^^^^^^^^^^^^^^^^^^^^^^^^^^^^^^^^^^^^^^^^^^^^
  File "/usr/local/lib/python3.11/site-packages/pymysql/connections.py", line 365, in __init__
    self.connect()
  File "/usr/local/lib/python3.11/site-packages/pymysql/connections.py", line 681, in connect
    self._request_authentication()
  File "/usr/local/lib/python3.11/site-packages/pymysql/connections.py", line 980, in _request_authentication
    auth_packet = _auth.caching_sha2_password_auth(self, auth_packet)
                  ^^^^^^^^^^^^^^^^^^^^^^^^^^^^^^^^^^^^^^^^^^^^^^^^^^^
  File "/usr/local/lib/python3.11/site-packages/pymysql/_auth.py", line 271, in caching_sha2_password_auth
    data = sha2_rsa_encrypt(conn.password, conn.salt, conn.server_public_key)
           ^^^^^^^^^^^^^^^^^^^^^^^^^^^^^^^^^^^^^^^^^^^^^^^^^^^^^^^^^^^^^^^^^^
  File "/usr/local/lib/python3.11/site-packages/pymysql/_auth.py", line 144, in sha2_rsa_encrypt
    raise RuntimeError(
RuntimeError: 'cryptography' package is required for sha256_password or caching_sha2_password auth methods
2025-08-28 09:50:30 | INFO     | phase1_sync | ✓ MySQL 連接成功：mysql:3306/erp_demo
2025-08-28 09:50:30 | INFO     | phase1_sync | ✓ Elasticsearch 已就緒
2025-08-28 09:50:30 | INFO     | phase1_sync | ✓ Elasticsearch 連接成功
2025-08-28 09:50:30 | INFO     | phase1_sync |   叢集名稱：elasticsearch-cluster
2025-08-28 09:50:30 | INFO     | phase1_sync |   叢集狀態：yellow
2025-08-28 09:50:30 | INFO     | phase1_sync |   節點數量：1
2025-08-28 09:50:30 | INFO     | phase1_sync | ============================================================
2025-08-28 09:50:30 | INFO     | phase1_sync | 階段一：MySQL 跨表同步系統啟動
2025-08-28 09:50:30 | INFO     | phase1_sync | 同步模式：incremental
2025-08-28 09:50:30 | INFO     | phase1_sync | 同步間隔：60 秒
2025-08-28 09:50:30 | INFO     | phase1_sync | 批次大小：500
2025-08-28 09:50:30 | INFO     | phase1_sync | ============================================================
2025-08-28 09:50:30 | INFO     | phase1_sync | 跨表搜索索引不存在，正在建立...
2025-08-28 09:50:30 | INFO     | phase1_sync | ============================================================
2025-08-28 09:50:30 | INFO     | phase1_sync | 初始化跨表搜索索引
2025-08-28 09:50:30 | INFO     | phase1_sync | ============================================================
2025-08-28 09:50:31 | ERROR    | phase1_sync | 建立跨表搜索索引失敗：400 Client Error: Bad Request for url: http://elasticsearch:9200/erp-cross-search
2025-08-28 09:50:31 | INFO     | phase1_sync | 執行索引初始化模式
2025-08-28 09:50:31 | INFO     | phase1_sync | ============================================================
2025-08-28 09:50:31 | INFO     | phase1_sync | 初始化跨表搜索索引
2025-08-28 09:50:31 | INFO     | phase1_sync | ============================================================
2025-08-28 09:50:31 | ERROR    | phase1_sync | 建立跨表搜索索引失敗：400 Client Error: Bad Request for url: http://elasticsearch:9200/erp-cross-search
2025-08-28 09:50:31 | INFO     | phase1_sync | 初始化失敗或索引已存在
2025-08-28 09:50:32 | INFO     | phase1_sync | ✓ MySQL 連接成功：mysql:3306/erp_demo
2025-08-28 09:50:32 | INFO     | phase1_sync | ✓ Elasticsearch 已就緒
2025-08-28 09:50:32 | INFO     | phase1_sync | ✓ Elasticsearch 連接成功
2025-08-28 09:50:32 | INFO     | phase1_sync |   叢集名稱：elasticsearch-cluster
2025-08-28 09:50:32 | INFO     | phase1_sync |   叢集狀態：yellow
2025-08-28 09:50:32 | INFO     | phase1_sync |   節點數量：1
2025-08-28 09:50:32 | INFO     | phase1_sync | ============================================================
2025-08-28 09:50:32 | INFO     | phase1_sync | 階段一：MySQL 跨表同步系統啟動
2025-08-28 09:50:32 | INFO     | phase1_sync | 同步模式：incremental
2025-08-28 09:50:32 | INFO     | phase1_sync | 同步間隔：60 秒
2025-08-28 09:50:32 | INFO     | phase1_sync | 批次大小：500
2025-08-28 09:50:32 | INFO     | phase1_sync | ============================================================
2025-08-28 09:50:32 | INFO     | phase1_sync | 跨表搜索索引不存在，正在建立...
2025-08-28 09:50:32 | INFO     | phase1_sync | ============================================================
2025-08-28 09:50:32 | INFO     | phase1_sync | 初始化跨表搜索索引
2025-08-28 09:50:32 | INFO     | phase1_sync | ============================================================
2025-08-28 09:50:32 | ERROR    | phase1_sync | 建立跨表搜索索引失敗：400 Client Error: Bad Request for url: http://elasticsearch:9200/erp-cross-search
2025-08-28 09:50:32 | INFO     | phase1_sync | 執行索引初始化模式
2025-08-28 09:50:32 | INFO     | phase1_sync | ============================================================
2025-08-28 09:50:32 | INFO     | phase1_sync | 初始化跨表搜索索引
2025-08-28 09:50:32 | INFO     | phase1_sync | ============================================================
2025-08-28 09:50:32 | ERROR    | phase1_sync | 建立跨表搜索索引失敗：400 Client Error: Bad Request for url: http://elasticsearch:9200/erp-cross-search
2025-08-28 09:50:32 | INFO     | phase1_sync | 初始化失敗或索引已存在
2025-08-28 09:50:33 | INFO     | phase1_sync | ✓ MySQL 連接成功：mysql:3306/erp_demo
2025-08-28 09:50:33 | INFO     | phase1_sync | ✓ Elasticsearch 已就緒
2025-08-28 09:50:33 | INFO     | phase1_sync | ✓ Elasticsearch 連接成功
2025-08-28 09:50:33 | INFO     | phase1_sync |   叢集名稱：elasticsearch-cluster
2025-08-28 09:50:33 | INFO     | phase1_sync |   叢集狀態：yellow
2025-08-28 09:50:33 | INFO     | phase1_sync |   節點數量：1
2025-08-28 09:50:33 | INFO     | phase1_sync | ============================================================
2025-08-28 09:50:33 | INFO     | phase1_sync | 階段一：MySQL 跨表同步系統啟動
2025-08-28 09:50:33 | INFO     | phase1_sync | 同步模式：incremental
2025-08-28 09:50:33 | INFO     | phase1_sync | 同步間隔：60 秒
2025-08-28 09:50:33 | INFO     | phase1_sync | 批次大小：500
2025-08-28 09:50:33 | INFO     | phase1_sync | ============================================================
2025-08-28 09:50:33 | INFO     | phase1_sync | 跨表搜索索引不存在，正在建立...
2025-08-28 09:50:33 | INFO     | phase1_sync | ============================================================
2025-08-28 09:50:33 | INFO     | phase1_sync | 初始化跨表搜索索引
2025-08-28 09:50:33 | INFO     | phase1_sync | ============================================================
2025-08-28 09:50:33 | ERROR    | phase1_sync | 建立跨表搜索索引失敗：400 Client Error: Bad Request for url: http://elasticsearch:9200/erp-cross-search
2025-08-28 09:50:33 | INFO     | phase1_sync | 執行索引初始化模式
2025-08-28 09:50:33 | INFO     | phase1_sync | ============================================================
2025-08-28 09:50:33 | INFO     | phase1_sync | 初始化跨表搜索索引
2025-08-28 09:50:33 | INFO     | phase1_sync | ============================================================
2025-08-28 09:50:33 | ERROR    | phase1_sync | 建立跨表搜索索引失敗：400 Client Error: Bad Request for url: http://elasticsearch:9200/erp-cross-search
2025-08-28 09:50:33 | INFO     | phase1_sync | 初始化失敗或索引已存在
2025-08-28 09:50:35 | INFO     | phase1_sync | ✓ MySQL 連接成功：mysql:3306/erp_demo
2025-08-28 09:50:35 | INFO     | phase1_sync | ✓ Elasticsearch 已就緒
2025-08-28 09:50:35 | INFO     | phase1_sync | ✓ Elasticsearch 連接成功
2025-08-28 09:50:35 | INFO     | phase1_sync |   叢集名稱：elasticsearch-cluster
2025-08-28 09:50:35 | INFO     | phase1_sync |   叢集狀態：yellow
2025-08-28 09:50:35 | INFO     | phase1_sync |   節點數量：1
2025-08-28 09:50:35 | INFO     | phase1_sync | ============================================================
2025-08-28 09:50:35 | INFO     | phase1_sync | 階段一：MySQL 跨表同步系統啟動
2025-08-28 09:50:35 | INFO     | phase1_sync | 同步模式：incremental
2025-08-28 09:50:35 | INFO     | phase1_sync | 同步間隔：60 秒
2025-08-28 09:50:35 | INFO     | phase1_sync | 批次大小：500
2025-08-28 09:50:35 | INFO     | phase1_sync | ============================================================
2025-08-28 09:50:35 | INFO     | phase1_sync | 跨表搜索索引不存在，正在建立...
2025-08-28 09:50:35 | INFO     | phase1_sync | ============================================================
2025-08-28 09:50:35 | INFO     | phase1_sync | 初始化跨表搜索索引
2025-08-28 09:50:35 | INFO     | phase1_sync | ============================================================
2025-08-28 09:50:35 | ERROR    | phase1_sync | 建立跨表搜索索引失敗：400 Client Error: Bad Request for url: http://elasticsearch:9200/erp-cross-search
2025-08-28 09:50:35 | INFO     | phase1_sync | 執行索引初始化模式
2025-08-28 09:50:35 | INFO     | phase1_sync | ============================================================
2025-08-28 09:50:35 | INFO     | phase1_sync | 初始化跨表搜索索引
2025-08-28 09:50:35 | INFO     | phase1_sync | ============================================================
2025-08-28 09:50:35 | ERROR    | phase1_sync | 建立跨表搜索索引失敗：400 Client Error: Bad Request for url: http://elasticsearch:9200/erp-cross-search
2025-08-28 09:50:35 | INFO     | phase1_sync | 初始化失敗或索引已存在
2025-08-28 09:51:41 | INFO     | phase1_sync | ✓ MySQL 連接成功：mysql:3306/erp_demo
2025-08-28 09:51:41 | INFO     | phase1_sync | ✓ Elasticsearch 已就緒
2025-08-28 09:51:41 | INFO     | phase1_sync | ✓ Elasticsearch 連接成功
2025-08-28 09:51:41 | INFO     | phase1_sync |   叢集名稱：elasticsearch-cluster
2025-08-28 09:51:41 | INFO     | phase1_sync |   叢集狀態：yellow
2025-08-28 09:51:41 | INFO     | phase1_sync |   節點數量：1
2025-08-28 09:51:41 | INFO     | phase1_sync | ============================================================
2025-08-28 09:51:41 | INFO     | phase1_sync | 階段一：MySQL 跨表同步系統啟動
2025-08-28 09:51:41 | INFO     | phase1_sync | 同步模式：incremental
2025-08-28 09:51:41 | INFO     | phase1_sync | 同步間隔：60 秒
2025-08-28 09:51:41 | INFO     | phase1_sync | 批次大小：500
2025-08-28 09:51:41 | INFO     | phase1_sync | ============================================================
2025-08-28 09:51:41 | INFO     | phase1_sync | 跨表搜索索引不存在，正在建立...
2025-08-28 09:51:41 | INFO     | phase1_sync | ============================================================
2025-08-28 09:51:41 | INFO     | phase1_sync | 初始化跨表搜索索引
2025-08-28 09:51:41 | INFO     | phase1_sync | ============================================================
2025-08-28 09:51:41 | ERROR    | phase1_sync | 建立跨表搜索索引失敗：400 Client Error: Bad Request for url: http://elasticsearch:9200/erp-cross-search
2025-08-28 09:51:41 | INFO     | phase1_sync | 執行索引初始化模式
2025-08-28 09:51:41 | INFO     | phase1_sync | ============================================================
2025-08-28 09:51:41 | INFO     | phase1_sync | 初始化跨表搜索索引
2025-08-28 09:51:41 | INFO     | phase1_sync | ============================================================
2025-08-28 09:51:41 | ERROR    | phase1_sync | 建立跨表搜索索引失敗：400 Client Error: Bad Request for url: http://elasticsearch:9200/erp-cross-search
2025-08-28 09:51:41 | INFO     | phase1_sync | 初始化失敗或索引已存在
2025-08-28 09:51:43 | INFO     | phase1_sync | ✓ MySQL 連接成功：mysql:3306/erp_demo
2025-08-28 09:51:43 | INFO     | phase1_sync | ✓ Elasticsearch 已就緒
2025-08-28 09:51:43 | INFO     | phase1_sync | ✓ Elasticsearch 連接成功
2025-08-28 09:51:43 | INFO     | phase1_sync |   叢集名稱：elasticsearch-cluster
2025-08-28 09:51:43 | INFO     | phase1_sync |   叢集狀態：yellow
2025-08-28 09:51:43 | INFO     | phase1_sync |   節點數量：1
2025-08-28 09:51:43 | INFO     | phase1_sync | ============================================================
2025-08-28 09:51:43 | INFO     | phase1_sync | 階段一：MySQL 跨表同步系統啟動
2025-08-28 09:51:43 | INFO     | phase1_sync | 同步模式：incremental
2025-08-28 09:51:43 | INFO     | phase1_sync | 同步間隔：60 秒
2025-08-28 09:51:43 | INFO     | phase1_sync | 批次大小：500
2025-08-28 09:51:43 | INFO     | phase1_sync | ============================================================
2025-08-28 09:51:43 | INFO     | phase1_sync | 跨表搜索索引不存在，正在建立...
2025-08-28 09:51:43 | INFO     | phase1_sync | ============================================================
2025-08-28 09:51:43 | INFO     | phase1_sync | 初始化跨表搜索索引
2025-08-28 09:51:43 | INFO     | phase1_sync | ============================================================
2025-08-28 09:51:43 | ERROR    | phase1_sync | 建立跨表搜索索引失敗：400 Client Error: Bad Request for url: http://elasticsearch:9200/erp-cross-search
2025-08-28 09:51:43 | INFO     | phase1_sync | 執行索引初始化模式
2025-08-28 09:51:43 | INFO     | phase1_sync | ============================================================
2025-08-28 09:51:43 | INFO     | phase1_sync | 初始化跨表搜索索引
2025-08-28 09:51:43 | INFO     | phase1_sync | ============================================================
2025-08-28 09:51:43 | ERROR    | phase1_sync | 建立跨表搜索索引失敗：400 Client Error: Bad Request for url: http://elasticsearch:9200/erp-cross-search
2025-08-28 09:51:43 | INFO     | phase1_sync | 初始化失敗或索引已存在
2025-08-28 09:51:45 | INFO     | phase1_sync | ✓ MySQL 連接成功：mysql:3306/erp_demo
2025-08-28 09:51:45 | INFO     | phase1_sync | ✓ Elasticsearch 已就緒
2025-08-28 09:51:45 | INFO     | phase1_sync | ✓ Elasticsearch 連接成功
2025-08-28 09:51:45 | INFO     | phase1_sync |   叢集名稱：elasticsearch-cluster
2025-08-28 09:51:45 | INFO     | phase1_sync |   叢集狀態：yellow
2025-08-28 09:51:45 | INFO     | phase1_sync |   節點數量：1
2025-08-28 09:51:45 | INFO     | phase1_sync | ============================================================
2025-08-28 09:51:45 | INFO     | phase1_sync | 階段一：MySQL 跨表同步系統啟動
2025-08-28 09:51:45 | INFO     | phase1_sync | 同步模式：incremental
2025-08-28 09:51:45 | INFO     | phase1_sync | 同步間隔：60 秒
2025-08-28 09:51:45 | INFO     | phase1_sync | 批次大小：500
2025-08-28 09:51:45 | INFO     | phase1_sync | ============================================================
2025-08-28 09:51:45 | INFO     | phase1_sync | 跨表搜索索引不存在，正在建立...
2025-08-28 09:51:45 | INFO     | phase1_sync | ============================================================
2025-08-28 09:51:45 | INFO     | phase1_sync | 初始化跨表搜索索引
2025-08-28 09:51:45 | INFO     | phase1_sync | ============================================================
2025-08-28 09:51:45 | ERROR    | phase1_sync | 建立跨表搜索索引失敗：400 Client Error: Bad Request for url: http://elasticsearch:9200/erp-cross-search
2025-08-28 09:51:45 | INFO     | phase1_sync | 執行索引初始化模式
2025-08-28 09:51:45 | INFO     | phase1_sync | ============================================================
2025-08-28 09:51:45 | INFO     | phase1_sync | 初始化跨表搜索索引
2025-08-28 09:51:45 | INFO     | phase1_sync | ============================================================
2025-08-28 09:51:45 | ERROR    | phase1_sync | 建立跨表搜索索引失敗：400 Client Error: Bad Request for url: http://elasticsearch:9200/erp-cross-search
2025-08-28 09:51:45 | INFO     | phase1_sync | 初始化失敗或索引已存在
2025-08-28 09:51:46 | INFO     | phase1_sync | ✓ MySQL 連接成功：mysql:3306/erp_demo
2025-08-28 09:51:46 | INFO     | phase1_sync | ✓ Elasticsearch 已就緒
2025-08-28 09:51:46 | INFO     | phase1_sync | ✓ Elasticsearch 連接成功
2025-08-28 09:51:46 | INFO     | phase1_sync |   叢集名稱：elasticsearch-cluster
2025-08-28 09:51:46 | INFO     | phase1_sync |   叢集狀態：yellow
2025-08-28 09:51:46 | INFO     | phase1_sync |   節點數量：1
2025-08-28 09:51:46 | INFO     | phase1_sync | ============================================================
2025-08-28 09:51:46 | INFO     | phase1_sync | 階段一：MySQL 跨表同步系統啟動
2025-08-28 09:51:46 | INFO     | phase1_sync | 同步模式：incremental
2025-08-28 09:51:46 | INFO     | phase1_sync | 同步間隔：60 秒
2025-08-28 09:51:46 | INFO     | phase1_sync | 批次大小：500
2025-08-28 09:51:46 | INFO     | phase1_sync | ============================================================
2025-08-28 09:51:46 | INFO     | phase1_sync | 跨表搜索索引不存在，正在建立...
2025-08-28 09:51:46 | INFO     | phase1_sync | ============================================================
2025-08-28 09:51:46 | INFO     | phase1_sync | 初始化跨表搜索索引
2025-08-28 09:51:46 | INFO     | phase1_sync | ============================================================
2025-08-28 09:51:46 | ERROR    | phase1_sync | 建立跨表搜索索引失敗：400 Client Error: Bad Request for url: http://elasticsearch:9200/erp-cross-search
2025-08-28 09:51:46 | INFO     | phase1_sync | 執行索引初始化模式
2025-08-28 09:51:46 | INFO     | phase1_sync | ============================================================
2025-08-28 09:51:46 | INFO     | phase1_sync | 初始化跨表搜索索引
2025-08-28 09:51:46 | INFO     | phase1_sync | ============================================================
2025-08-28 09:51:46 | ERROR    | phase1_sync | 建立跨表搜索索引失敗：400 Client Error: Bad Request for url: http://elasticsearch:9200/erp-cross-search
2025-08-28 09:51:46 | INFO     | phase1_sync | 初始化失敗或索引已存在
2025-08-28 09:51:48 | INFO     | phase1_sync | ✓ MySQL 連接成功：mysql:3306/erp_demo
2025-08-28 09:51:48 | INFO     | phase1_sync | ✓ Elasticsearch 已就緒
2025-08-28 09:51:48 | INFO     | phase1_sync | ✓ Elasticsearch 連接成功
2025-08-28 09:51:48 | INFO     | phase1_sync |   叢集名稱：elasticsearch-cluster
2025-08-28 09:51:48 | INFO     | phase1_sync |   叢集狀態：yellow
2025-08-28 09:51:48 | INFO     | phase1_sync |   節點數量：1
2025-08-28 09:51:48 | INFO     | phase1_sync | ============================================================
2025-08-28 09:51:48 | INFO     | phase1_sync | 階段一：MySQL 跨表同步系統啟動
2025-08-28 09:51:48 | INFO     | phase1_sync | 同步模式：incremental
2025-08-28 09:51:48 | INFO     | phase1_sync | 同步間隔：60 秒
2025-08-28 09:51:48 | INFO     | phase1_sync | 批次大小：500
2025-08-28 09:51:48 | INFO     | phase1_sync | ============================================================
2025-08-28 09:51:48 | INFO     | phase1_sync | 跨表搜索索引不存在，正在建立...
2025-08-28 09:51:48 | INFO     | phase1_sync | ============================================================
2025-08-28 09:51:48 | INFO     | phase1_sync | 初始化跨表搜索索引
2025-08-28 09:51:48 | INFO     | phase1_sync | ============================================================
2025-08-28 09:51:48 | ERROR    | phase1_sync | 建立跨表搜索索引失敗：400 Client Error: Bad Request for url: http://elasticsearch:9200/erp-cross-search
2025-08-28 09:51:48 | INFO     | phase1_sync | 執行索引初始化模式
2025-08-28 09:51:48 | INFO     | phase1_sync | ============================================================
2025-08-28 09:51:48 | INFO     | phase1_sync | 初始化跨表搜索索引
2025-08-28 09:51:48 | INFO     | phase1_sync | ============================================================
2025-08-28 09:51:48 | ERROR    | phase1_sync | 建立跨表搜索索引失敗：400 Client Error: Bad Request for url: http://elasticsearch:9200/erp-cross-search
2025-08-28 09:51:48 | INFO     | phase1_sync | 初始化失敗或索引已存在
2025-08-28 09:51:51 | INFO     | phase1_sync | ✓ MySQL 連接成功：mysql:3306/erp_demo
2025-08-28 09:51:51 | INFO     | phase1_sync | ✓ Elasticsearch 已就緒
2025-08-28 09:51:51 | INFO     | phase1_sync | ✓ Elasticsearch 連接成功
2025-08-28 09:51:51 | INFO     | phase1_sync |   叢集名稱：elasticsearch-cluster
2025-08-28 09:51:51 | INFO     | phase1_sync |   叢集狀態：yellow
2025-08-28 09:51:51 | INFO     | phase1_sync |   節點數量：1
2025-08-28 09:51:51 | INFO     | phase1_sync | ============================================================
2025-08-28 09:51:51 | INFO     | phase1_sync | 階段一：MySQL 跨表同步系統啟動
2025-08-28 09:51:51 | INFO     | phase1_sync | 同步模式：incremental
2025-08-28 09:51:51 | INFO     | phase1_sync | 同步間隔：60 秒
2025-08-28 09:51:51 | INFO     | phase1_sync | 批次大小：500
2025-08-28 09:51:51 | INFO     | phase1_sync | ============================================================
2025-08-28 09:51:51 | INFO     | phase1_sync | 跨表搜索索引不存在，正在建立...
2025-08-28 09:51:51 | INFO     | phase1_sync | ============================================================
2025-08-28 09:51:51 | INFO     | phase1_sync | 初始化跨表搜索索引
2025-08-28 09:51:51 | INFO     | phase1_sync | ============================================================
2025-08-28 09:51:51 | ERROR    | phase1_sync | 建立跨表搜索索引失敗：400 Client Error: Bad Request for url: http://elasticsearch:9200/erp-cross-search
2025-08-28 09:51:51 | INFO     | phase1_sync | 執行索引初始化模式
2025-08-28 09:51:51 | INFO     | phase1_sync | ============================================================
2025-08-28 09:51:51 | INFO     | phase1_sync | 初始化跨表搜索索引
2025-08-28 09:51:51 | INFO     | phase1_sync | ============================================================
2025-08-28 09:51:51 | ERROR    | phase1_sync | 建立跨表搜索索引失敗：400 Client Error: Bad Request for url: http://elasticsearch:9200/erp-cross-search
2025-08-28 09:51:51 | INFO     | phase1_sync | 初始化失敗或索引已存在
2025-08-28 09:51:55 | INFO     | phase1_sync | ✓ MySQL 連接成功：mysql:3306/erp_demo
2025-08-28 09:51:55 | INFO     | phase1_sync | ✓ Elasticsearch 已就緒
2025-08-28 09:51:55 | INFO     | phase1_sync | ✓ Elasticsearch 連接成功
2025-08-28 09:51:55 | INFO     | phase1_sync |   叢集名稱：elasticsearch-cluster
2025-08-28 09:51:55 | INFO     | phase1_sync |   叢集狀態：yellow
2025-08-28 09:51:55 | INFO     | phase1_sync |   節點數量：1
2025-08-28 09:51:55 | INFO     | phase1_sync | ============================================================
2025-08-28 09:51:55 | INFO     | phase1_sync | 階段一：MySQL 跨表同步系統啟動
2025-08-28 09:51:55 | INFO     | phase1_sync | 同步模式：incremental
2025-08-28 09:51:55 | INFO     | phase1_sync | 同步間隔：60 秒
2025-08-28 09:51:55 | INFO     | phase1_sync | 批次大小：500
2025-08-28 09:51:55 | INFO     | phase1_sync | ============================================================
2025-08-28 09:51:55 | INFO     | phase1_sync | 跨表搜索索引不存在，正在建立...
2025-08-28 09:51:55 | INFO     | phase1_sync | ============================================================
2025-08-28 09:51:55 | INFO     | phase1_sync | 初始化跨表搜索索引
2025-08-28 09:51:55 | INFO     | phase1_sync | ============================================================
2025-08-28 09:51:55 | ERROR    | phase1_sync | 建立跨表搜索索引失敗：400 Client Error: Bad Request for url: http://elasticsearch:9200/erp-cross-search
2025-08-28 09:51:55 | INFO     | phase1_sync | 執行索引初始化模式
2025-08-28 09:51:55 | INFO     | phase1_sync | ============================================================
2025-08-28 09:51:55 | INFO     | phase1_sync | 初始化跨表搜索索引
2025-08-28 09:51:55 | INFO     | phase1_sync | ============================================================
2025-08-28 09:51:55 | ERROR    | phase1_sync | 建立跨表搜索索引失敗：400 Client Error: Bad Request for url: http://elasticsearch:9200/erp-cross-search
2025-08-28 09:51:55 | INFO     | phase1_sync | 初始化失敗或索引已存在
